Workbook
Name I1.18: '7'!#REF!
Name I1.18: '8'!#REF!
Name I1.18: '9'!#REF!
Name I1.18_1: '7'!#REF!
Name I1.18_1: '8'!#REF!
Name I1.18_1: '9'!#REF!

Sheet Граф_Наблюдения
E2: Скважина | F2: 13 | T2: Скважина | U2: 13 | AP2: Скважина | AQ2: =U2 -> 13
E3: Дата нулевого цикла измерений | F3: 45517 | T3: Дата нулевого цикла измерений | U3: 45517 | AE3: Дата нулевого цикла измерений | AF3: =U3 -> 45517 | AP3: Дата нулевого цикла измерений | AQ3: =U3 -> 45517
A5: Абсолютное отклонение скважины в направлении Юг-Север (мм) | G5: Абсолютное отклонение скважины в направлении Запад-Восток (мм) | K5: Абсолютное отклонение скважины суммарное (мм) | P5: Отклонение от референсного положения в направлении Юг-Север (мм) | V5: Отклонение от референсного положения в направлении Запад-Восток (мм) | AA5: Общее отклонение от референсного положения (мм) | AF5: Азимут отклонения, град

Sheet "0" цикл 24.06
B1: Нулевой цикл (24.06) | K1: Аз скв | L1: 180
A2: Глубина | B2: X1 | C2: X2 | D2: X абсолютное (угл. Сек) | E2: Перемещение по X, (мм), 01.03.24 | F2: Y1 | G2: Y2 | H2: Y абсолютное (угл. Сек) | I2: Перемещение по Y, (мм), 15.03.24 | J2: Суммарное перемещение, мм | K2: Азимут (в системе координат скважины) | L2: Азимут, абсолютный | M2: D сев | N2: D восток | O2: Dрез | P2: ΔD сев | Q2: ΔD восток | R2: ΔD | T2: Аз откл
A3: 0 | B3: -1896.5 | C3: -5592.9 | D3: =(B3-C3)/2 -> 1848.2 | E3: =0.5*SIN(D3/3600*PI()/180)*1000+E4 -> -712.54381 | F3: -937.8 | G3: 3616.3 | H3: =(F3-G3)/2 -> -2277.05 | I3: =0.5*SIN(H3/3600*PI()/180)*1000+I4 -> 586.7014 | J3: =SQRT(E3^2+I3^2) -> 923.00445 | K3: =IF(E3>=0,180-DEGREES(ASIN(-I3/J3)),IF(E3<0,DEGREES(ASIN(-I3/J3)),360-DEGREES(ASIN(I3/J3)))) -> -39.467698 | L3: =IF((K3+$L$1)<=360,K3+$L$1,K3+$L$1-360) -> 140.5323 | M3: =J3*COS(RADIANS(L3)) -> -712.54381 | N3: =J3*SIN(RADIANS(L3)) -> 586.7014 | O3: =SQRT(N3^2+M3^2) -> 923.00445 | P3: =M3 -> -712.54381 | Q3: =N3 -> 586.7014 | R3: =SQRT(P3^2+Q3^2) -> 923.00445 | S3: =IF(R3=0,0,IF(P3>=0,DEGREES(ASIN(Q3/R3)),(180-DEGREES(ASIN(Q3/R3))))) -> 140.5323 | T3: =IF(S3<0,360+S3,S3) -> 140.5323
A4: 0.5 | B4: -2364.2 | C4: -7831.4 | D4: =(B4-C4)/2 -> 2733.6 | E4: =0.5*SIN(D4/3600*PI()/180)*1000+E5 -> -717.02391 | F4: -386.7 | G4: 5773.3 | H4: =(F4-G4)/2 -> -3080 | I4: =0.5*SIN(H4/3600*PI()/180)*1000+I5 -> 592.22101 | J4: =SQRT(E4^2+I4^2) -> 929.97259 | K4: =IF(E4>=0,180-DEGREES(ASIN(-I4/J4)),IF(E4<0,DEGREES(ASIN(-I4/J4)),360-DEGREES(ASIN(I4/J4)))) -> -39.554771 | L4: =IF((K4+$L$1)<=360,K4+$L$1,K4+$L$1-360) -> 140.44523 | M4: =J4*COS(RADIANS(L4)) -> -717.02391 | N4: =J4*SIN(RADIANS(L4)) -> 592.22101 | O4: =SQRT(N4^2+M4^2) -> 929.97259 | P4: =M4 -> -717.02391 | Q4: =N4 -> 592.22101 | R4: =SQRT(P4^2+Q4^2) -> 929.97259 | S4: =IF(R4=0,0,IF(P4>=0,DEGREES(ASIN(Q4/R4)),(180-DEGREES(ASIN(Q4/R4))))) -> 140.44523 | T4: =IF(S4<0,360+S4,S4) -> 140.44523
A5: 1 | B5: -3432.6 | C5: -7218.9 | D5: =(B5-C5)/2 -> 1893.15 | E5: =0.5*SIN(D5/3600*PI()/180)*1000+E6 -> -723.65015 | F5: 598.5 | G5: 5387.3 | H5: =(F5-G5)/2 -> -2394.4 | I5: =0.5*SIN(H5/3600*PI()/180)*1000+I6 -> 599.68687 | J5: =SQRT(E5^2+I5^2) -> 939.83716 | K5: =IF(E5>=0,180-DEGREES(ASIN(-I5/J5)),IF(E5<0,DEGREES(ASIN(-I5/J5)),360-DEGREES(ASIN(I5/J5)))) -> -39.648448 | L5: =IF((K5+$L$1)<=360,K5+$L$1,K5+$L$1-360) -> 140.35155 | M5: =J5*COS(RADIANS(L5)) -> -723.65015 | N5: =J5*SIN(RADIANS(L5)) -> 599.68687 | O5: =SQRT(N5^2+M5^2) -> 939.83716 | P5: =M5 -> -723.65015 | Q5: =N5 -> 599.68687 | R5: =SQRT(P5^2+Q5^2) -> 939.83716 | S5: =IF(R5=0,0,IF(P5>=0,DEGREES(ASIN(Q5/R5)),(180-DEGREES(ASIN(Q5/R5))))) -> 140.35155 | T5: =IF(S5<0,360+S5,S5) -> 140.35155
A6: 1.5 | B6: -4867.4 | C6: -6719.7 | D6: =(B6-C6)/2 -> 926.15 | E6: =0.5*SIN(D6/3600*PI()/180)*1000+E7 -> -728.23921 | F6: 2158 | G6: 4850.3 | H6: =(F6-G6)/2 -> -1346.15 | I6: =0.5*SIN(H6/3600*PI()/180)*1000+I7 -> 605.49093 | J6: =SQRT(E6^2+I6^2) -> 947.07529 | K6: =IF(E6>=0,180-DEGREES(ASIN(-I6/J6)),IF(E6<0,DEGREES(ASIN(-I6/J6)),360-DEGREES(ASIN(I6/J6)))) -> -39.741663 | L6: =IF((K6+$L$1)<=360,K6+$L$1,K6+$L$1-360) -> 140.25834 | M6: =J6*COS(RADIANS(L6)) -> -728.23921 | N6: =J6*SIN(RADIANS(L6)) -> 605.49093 | O6: =SQRT(N6^2+M6^2) -> 947.07529 | P6: =M6 -> -728.23921 | Q6: =N6 -> 605.49093 | R6: =SQRT(P6^2+Q6^2) -> 947.07529 | S6: =IF(R6=0,0,IF(P6>=0,DEGREES(ASIN(Q6/R6)),(180-DEGREES(ASIN(Q6/R6))))) -> 140.25834 | T6: =IF(S6<0,360+S6,S6) -> 140.25834
A7: 2 | B7: -5311.3 | C7: -5929.4 | D7: =(B7-C7)/2 -> 309.05 | E7: =0.5*SIN(D7/3600*PI()/180)*1000+E8 -> -730.48426 | F7: 2514.5 | G7: 4084.5 | H7: =(F7-G7)/2 -> -785 | I7: =0.5*SIN(H7/3600*PI()/180)*1000+I8 -> 608.75406 | J7: =SQRT(E7^2+I7^2) -> 950.8884 | K7: =IF(E7>=0,180-DEGREES(ASIN(-I7/J7)),IF(E7<0,DEGREES(ASIN(-I7/J7)),360-DEGREES(ASIN(I7/J7)))) -> -39.806366 | L7: =IF((K7+$L$1)<=360,K7+$L$1,K7+$L$1-360) -> 140.19363 | M7: =J7*COS(RADIANS(L7)) -> -730.48426 | N7: =J7*SIN(RADIANS(L7)) -> 608.75406 | O7: =SQRT(N7^2+M7^2) -> 950.8884 | P7: =M7 -> -730.48426 | Q7: =N7 -> 608.75406 | R7: =SQRT(P7^2+Q7^2) -> 950.8884 | S7: =IF(R7=0,0,IF(P7>=0,DEGREES(ASIN(Q7/R7)),(180-DEGREES(ASIN(Q7/R7))))) -> 140.19363 | T7: =IF(S7<0,360+S7,S7) -> 140.19363
A8: 2.5 | B8: -5808.5 | C8: -5026.3 | D8: =(B8-C8)/2 -> -391.1 | E8: =0.5*SIN(D8/3600*PI()/180)*1000+E9 -> -731.23342 | F8: 2923.5 | G8: 3084.2 | H8: =(F8-G8)/2 -> -80.35 | I8: =0.5*SIN(H8/3600*PI()/180)*1000+I9 -> 610.65695 | J8: =SQRT(E8^2+I8^2) -> 952.68264 | K8: =IF(E8>=0,180-DEGREES(ASIN(-I8/J8)),IF(E8<0,DEGREES(ASIN(-I8/J8)),360-DEGREES(ASIN(I8/J8)))) -> -39.865438 | L8: =IF((K8+$L$1)<=360,K8+$L$1,K8+$L$1-360) -> 140.13456 | M8: =J8*COS(RADIANS(L8)) -> -731.23342 | N8: =J8*SIN(RADIANS(L8)) -> 610.65695 | O8: =SQRT(N8^2+M8^2) -> 952.68264 | P8: =M8 -> -731.23342 | Q8: =N8 -> 610.65695 | R8: =SQRT(P8^2+Q8^2) -> 952.68264 | S8: =IF(R8=0,0,IF(P8>=0,DEGREES(ASIN(Q8/R8)),(180-DEGREES(ASIN(Q8/R8))))) -> 140.13456 | T8: =IF(S8<0,360+S8,S8) -> 140.13456
A9: 3 | B9: -6555.7 | C9: -4151 | D9: =(B9-C9)/2 -> -1202.35 | E9: =0.5*SIN(D9/3600*PI()/180)*1000+E10 -> -730.28536 | F9: 3821.4 | G9: 2276.9 | H9: =(F9-G9)/2 -> 772.25 | I9: =0.5*SIN(H9/3600*PI()/180)*1000+I10 -> 610.85173 | J9: =SQRT(E9^2+I9^2) -> 952.08011 | K9: =IF(E9>=0,180-DEGREES(ASIN(-I9/J9)),IF(E9<0,DEGREES(ASIN(-I9/J9)),360-DEGREES(ASIN(I9/J9)))) -> -39.911006 | L9: =IF((K9+$L$1)<=360,K9+$L$1,K9+$L$1-360) -> 140.08899 | M9: =J9*COS(RADIANS(L9)) -> -730.28536 | N9: =J9*SIN(RADIANS(L9)) -> 610.85173 | O9: =SQRT(N9^2+M9^2) -> 952.08011 | P9: =M9 -> -730.28536 | Q9: =N9 -> 610.85173 | R9: =SQRT(P9^2+Q9^2) -> 952.08011 | S9: =IF(R9=0,0,IF(P9>=0,DEGREES(ASIN(Q9/R9)),(180-DEGREES(ASIN(Q9/R9))))) -> 140.08899 | T9: =IF(S9<0,360+S9,S9) -> 140.08899
A10: 3.5 | B10: -7445.6 | C10: -3603.8 | D10: =(B10-C10)/2 -> -1920.9 | E10: =0.5*SIN(D10/3600*PI()/180)*1000+E11 -> -727.3708 | F10: 4826.1 | G10: 1606.5 | H10: =(F10-G10)/2 -> 1609.8 | I10: =0.5*SIN(H10/3600*PI()/180)*1000+I11 -> 608.97974 | J10: =SQRT(E10^2+I10^2) -> 948.64356 | K10: =IF(E10>=0,180-DEGREES(ASIN(-I10/J10)),IF(E10<0,DEGREES(ASIN(-I10/J10)),360-DEGREES(ASIN(I10/J10)))) -> -39.937223 | L10: =IF((K10+$L$1)<=360,K10+$L$1,K10+$L$1-360) -> 140.06278 | M10: =J10*COS(RADIANS(L10)) -> -727.3708 | N10: =J10*SIN(RADIANS(L10)) -> 608.97974 | O10: =SQRT(N10^2+M10^2) -> 948.64356 | P10: =M10 -> -727.3708 | Q10: =N10 -> 608.97974 | R10: =SQRT(P10^2+Q10^2) -> 948.64356 | S10: =IF(R10=0,0,IF(P10>=0,DEGREES(ASIN(Q10/R10)),(180-DEGREES(ASIN(Q10/R10))))) -> 140.06278 | T10: =IF(S10<0,360+S10,S10) -> 140.06278
A11: 4 | B11: -6909.9 | C11: -3436.8 | D11: =(B11-C11)/2 -> -1736.55 | E11: =0.5*SIN(D11/3600*PI()/180)*1000+E12 -> -722.71448 | F11: 3979 | G11: 1518.5 | H11: =(F11-G11)/2 -> 1230.25 | I11: =0.5*SIN(H11/3600*PI()/180)*1000+I12 -> 605.07752 | J11: =SQRT(E11^2+I11^2) -> 942.56831 | K11: =IF(E11>=0,180-DEGREES(ASIN(-I11/J11)),IF(E11<0,DEGREES(ASIN(-I11/J11)),360-DEGREES(ASIN(I11/J11)))) -> -39.937047 | L11: =IF((K11+$L$1)<=360,K11+$L$1,K11+$L$1-360) -> 140.06295 | M11: =J11*COS(RADIANS(L11)) -> -722.71448 | N11: =J11*SIN(RADIANS(L11)) -> 605.07752 | O11: =SQRT(N11^2+M11^2) -> 942.56831 | P11: =M11 -> -722.71448 | Q11: =N11 -> 605.07752 | R11: =SQRT(P11^2+Q11^2) -> 942.56831 | S11: =IF(R11=0,0,IF(P11>=0,DEGREES(ASIN(Q11/R11)),(180-DEGREES(ASIN(Q11/R11))))) -> 140.06295 | T11: =IF(S11<0,360+S11,S11) -> 140.06295
A12: 4.5 | B12: -5428.5 | C12: -3307.3 | D12: =(B12-C12)/2 -> -1060.6 | E12: =0.5*SIN(D12/3600*PI()/180)*1000+E13 -> -718.50501 | F12: 2629.4 | G12: 1346.7 | H12: =(F12-G12)/2 -> 641.35 | I12: =0.5*SIN(H12/3600*PI()/180)*1000+I13 -> 602.09532 | J12: =SQRT(E12^2+I12^2) -> 937.42638 | K12: =IF(E12>=0,180-DEGREES(ASIN(-I12/J12)),IF(E12<0,DEGREES(ASIN(-I12/J12)),360-DEGREES(ASIN(I12/J12)))) -> -39.962451 | L12: =IF((K12+$L$1)<=360,K12+$L$1,K12+$L$1-360) -> 140.03755 | M12: =J12*COS(RADIANS(L12)) -> -718.50501 | N12: =J12*SIN(RADIANS(L12)) -> 602.09532 | O12: =SQRT(N12^2+M12^2) -> 937.42638 | P12: =M12 -> -718.50501 | Q12: =N12 -> 602.09532 | R12: =SQRT(P12^2+Q12^2) -> 937.42638 | S12: =IF(R12=0,0,IF(P12>=0,DEGREES(ASIN(Q12/R12)),(180-DEGREES(ASIN(Q12/R12))))) -> 140.03755 | T12: =IF(S12<0,360+S12,S12) -> 140.03755
A13: 5 | B13: -3640.7 | C13: -3557.9 | D13: =(B13-C13)/2 -> -41.4 | E13: =0.5*SIN(D13/3600*PI()/180)*1000+E14 -> -715.93405 | F13: 903.9 | G13: 1645.4 | H13: =(F13-G13)/2 -> -370.75 | I13: =0.5*SIN(H13/3600*PI()/180)*1000+I14 -> 600.54065 | J13: =SQRT(E13^2+I13^2) -> 934.4574 | K13: =IF(E13>=0,180-DEGREES(ASIN(-I13/J13)),IF(E13<0,DEGREES(ASIN(-I13/J13)),360-DEGREES(ASIN(I13/J13)))) -> -39.990637 | L13: =IF((K13+$L$1)<=360,K13+$L$1,K13+$L$1-360) -> 140.00936 | M13: =J13*COS(RADIANS(L13)) -> -715.93405 | N13: =J13*SIN(RADIANS(L13)) -> 600.54065 | O13: =SQRT(N13^2+M13^2) -> 934.4574 | P13: =M13 -> -715.93405 | Q13: =N13 -> 600.54065 | R13: =SQRT(P13^2+Q13^2) -> 934.4574 | S13: =IF(R13=0,0,IF(P13>=0,DEGREES(ASIN(Q13/R13)),(180-DEGREES(ASIN(Q13/R13))))) -> 140.00936 | T13: =IF(S13<0,360+S13,S13) -> 140.00936
A14: 5.5 | B14: -2168.3 | C14: -3645.9 | D14: =(B14-C14)/2 -> 738.8 | E14: =0.5*SIN(D14/3600*PI()/180)*1000+E15 -> -715.8337 | F14: -647.6 | G14: 1688.3 | H14: =(F14-G14)/2 -> -1167.95 | I14: =0.5*SIN(H14/3600*PI()/180)*1000+I15 -> 601.43937 | J14: =SQRT(E14^2+I14^2) -> 934.9584 | K14: =IF(E14>=0,180-DEGREES(ASIN(-I14/J14)),IF(E14<0,DEGREES(ASIN(-I14/J14)),360-DEGREES(ASIN(I14/J14)))) -> -40.036785 | L14: =IF((K14+$L$1)<=360,K14+$L$1,K14+$L$1-360) -> 139.96322 | M14: =J14*COS(RADIANS(L14)) -> -715.8337 | N14: =J14*SIN(RADIANS(L14)) -> 601.43937 | O14: =SQRT(N14^2+M14^2) -> 934.9584 | P14: =M14 -> -715.8337 | Q14: =N14 -> 601.43937 | R14: =SQRT(P14^2+Q14^2) -> 934.9584 | S14: =IF(R14=0,0,IF(P14>=0,DEGREES(ASIN(Q14/R14)),(180-DEGREES(ASIN(Q14/R14))))) -> 139.96322 | T14: =IF(S14<0,360+S14,S14) -> 139.96322
... A121: 59 | B121: 695.3 | C121: 11079.3 | D121: =(B121-C121)/2 -> -5192 | E121: =0.5*SIN(D121/3600*PI()/180)*1000+E122 -> -26.071042 | F121: -3562.2 | G121: -13073.4 | H121: =(F121-G121)/2 -> 4755.6 | I121: =0.5*SIN(H121/3600*PI()/180)*1000+I122 -> 23.995721 | J121: =SQRT(E121^2+I121^2) -> 35.432949 | K121: =IF(E121>=0,180-DEGREES(ASIN(-I121/J121)),IF(E121<0,DEGREES(ASIN(-I121/J121)),360-DEGREES(ASIN(I121/J121)))) -> -42.626387 | L121: =IF((K121+$L$1)<=360,K121+$L$1,K121+$L$1-360) -> 137.37361 | M121: =J121*COS(RADIANS(L121)) -> -26.071042 | N121: =J121*SIN(RADIANS(L121)) -> 23.995721 | O121: =SQRT(N121^2+M121^2) -> 35.432949 | P121: =M121 -> -26.071042 | Q121: =N121 -> 23.995721 | R121: =SQRT(P121^2+Q121^2) -> 35.432949 | S121: =IF(R121=0,0,IF(P121>=0,DEGREES(ASIN(Q121/R121)),(180-DEGREES(ASIN(Q121/R121))))) -> 137.37361 | T121: =IF(S121<0,360+S121,S121) -> 137.37361
A122: 59.5 | B122: 563.5 | C122: 11193.1 | D122: =(B122-C122)/2 -> -5314.8 | E122: =0.5*SIN(D123/3600*PI()/180)*1000+E123 -> -13.486608 | F122: -3385.2 | G122: -13136.6 | H122: =(F122-G122)/2 -> 4875.7 | I122: =0.5*SIN(H123/3600*PI()/180)*1000+I123 -> 12.468842 | J122: =SQRT(E122^2+I122^2) -> 18.367379 | K122: =IF(E122>=0,180-DEGREES(ASIN(-I122/J122)),IF(E122<0,DEGREES(ASIN(-I122/J122)),360-DEGREES(ASIN(I122/J122)))) -> -42.754467 | L122: =IF((K122+$L$1)<=360,K122+$L$1,K122+$L$1-360) -> 137.24553 | M122: =J122*COS(RADIANS(L122)) -> -13.486608 | N122: =J122*SIN(RADIANS(L122)) -> 12.468842 | O122: =SQRT(N122^2+M122^2) -> 18.367379 | P122: =M122 -> -13.486608 | Q122: =N122 -> 12.468842 | R122: =SQRT(P122^2+Q122^2) -> 18.367379 | S122: =IF(R122=0,0,IF(P122>=0,DEGREES(ASIN(Q122/R122)),(180-DEGREES(ASIN(Q122/R122))))) -> 137.24553 | T122: =IF(S122<0,360+S122,S122) -> 137.24553
A123: 60 | B123: 431.7 | C123: 11560.3 | D123: =(B123-C123)/2 -> -5564.3 | E123: 0 | F123: -3223.5 | G123: -13512.1 | H123: =(F123-G123)/2 -> 5144.3 | I123: 0 | J123: =SQRT(E123^2+I123^2) -> 0 | K123: =IF(E123>=0,180-DEGREES(ASIN(-I123/J123)),IF(E123<0,DEGREES(ASIN(-I123/J123)),360-DEGREES(ASIN(I123/J123)))) -> #DIV/0! | L123: =IF((K123+$L$1)<=360,K123+$L$1,K123+$L$1-360) -> #DIV/0! | M123: =J123*COS(RADIANS(L123)) -> #DIV/0! | N123: =J123*SIN(RADIANS(L123)) -> #DIV/0! | O123: =SQRT(N123^2+M123^2) -> #DIV/0! | P123: =M123 -> #DIV/0! | Q123: =N123 -> #DIV/0! | R123: =SQRT(P123^2+Q123^2) -> #DIV/0! | S123: =IF(R123=0,0,IF(P123>=0,DEGREES(ASIN(Q123/R123)),(180-DEGREES(ASIN(Q123/R123))))) -> #DIV/0! | T123: =IF(S123<0,360+S123,S123) -> #DIV/0!

Sheet 21.10.24
B1: Цикл 1 (21.10.24) | K1: Аз скв | L1: 180
A2: Глубина | B2: X1 | C2: X2 | D2: X абсолютное (угл. Сек) | E2: Горизонтальное отклонение скважины от вертикали по оси X, (мм) | F2: Y1 | G2: Y2 | H2: Y абсолютное (угл. Сек) | I2: Горизонтальное отклонение скважины от вертикали по оси Y, (мм) | J2: Горизонтальное отклонение скважины от вертикали результирующее (мм) | K2: Азимут (в системе координат скважины) | L2: Азимут, абсолютный | M2: D сев | N2: D восток | O2: Dрез | P2: ΔD сев | Q2: ΔD восток | R2: ΔD | T2: Аз откл
A3: 0 | B3: -3344.9 | C3: -5497.5 | D3: =(B3-C3)/2 -> 1076.3 | E3: =0.5*SIN(D3/3600*PI()/180)*1000+E4 -> -715.0092 | F3: 804 | G3: 3778.5 | H3: =(F3-G3)/2 -> -1487.25 | I3: =0.5*SIN(H3/3600*PI()/180)*1000+I4 -> 624.14735 | J3: =SQRT(E3^2+I3^2) -> 949.10382 | K3: =IF(E3>=0,180-DEGREES(ASIN(-I3/J3)),IF(E3<0,DEGREES(ASIN(-I3/J3)),360-DEGREES(ASIN(I3/J3)))) -> -41.118427 | L3: =IF((K3+$L$1)<=360,K3+$L$1,K3+$L$1-360) -> 138.88157 | M3: =J3*COS(RADIANS(L3)) -> -715.0092 | N3: =J3*SIN(RADIANS(L3)) -> 624.14735 | O3: =SQRT(N3^2+M3^2) -> 949.10382 | P3: =M3-'"0" цикл 24.06'!M3 -> -2.4653862 | Q3: =N3-'"0" цикл 24.06'!N3 -> 37.445946 | R3: =SQRT(P3^2+Q3^2) -> 37.527017 | S3: =IF(R3=0,0,IF(P3>=0,DEGREES(ASIN(Q3/R3)),(180-DEGREES(ASIN(Q3/R3))))) -> 93.766834 | T3: =IF(S3<0,360+S3,S3) -> 93.766834
A4: 0.5 | B4: -2776 | C4: -7311 | D4: =(B4-C4)/2 -> 2267.5 | E4: =0.5*SIN(D4/3600*PI()/180)*1000+E5 -> -717.61821 | F4: 387.7 | G4: 5549.9 | H4: =(F4-G4)/2 -> -2581.1 | I4: =0.5*SIN(H4/3600*PI()/180)*1000+I5 -> 627.75251 | J4: =SQRT(E4^2+I4^2) -> 953.44067 | K4: =IF(E4>=0,180-DEGREES(ASIN(-I4/J4)),IF(E4<0,DEGREES(ASIN(-I4/J4)),360-DEGREES(ASIN(I4/J4)))) -> -41.178534 | L4: =IF((K4+$L$1)<=360,K4+$L$1,K4+$L$1-360) -> 138.82147 | M4: =J4*COS(RADIANS(L4)) -> -717.61821 | N4: =J4*SIN(RADIANS(L4)) -> 627.75251 | O4: =SQRT(N4^2+M4^2) -> 953.44067 | P4: =M4-'"0" цикл 24.06'!M4 -> -0.59429592 | Q4: =N4-'"0" цикл 24.06'!N4 -> 35.531498 | R4: =SQRT(P4^2+Q4^2) -> 35.536468 | S4: =IF(R4=0,0,IF(P4>=0,DEGREES(ASIN(Q4/R4)),(180-DEGREES(ASIN(Q4/R4))))) -> 90.958234 | T4: =IF(S4<0,360+S4,S4) -> 90.958234
A5: 1 | B5: -2687.8 | C5: -7179.6 | D5: =(B5-C5)/2 -> 2245.9 | E5: =0.5*SIN(D5/3600*PI()/180)*1000+E6 -> -723.11467 | F5: 291.7 | G5: 5267.6 | H5: =(F5-G5)/2 -> -2487.95 | I5: =0.5*SIN(H5/3600*PI()/180)*1000+I6 -> 634.00911 | J5: =SQRT(E5^2+I5^2) -> 961.69766 | K5: =IF(E5>=0,180-DEGREES(ASIN(-I5/J5)),IF(E5<0,DEGREES(ASIN(-I5/J5)),360-DEGREES(ASIN(I5/J5)))) -> -41.243485 | L5: =IF((K5+$L$1)<=360,K5+$L$1,K5+$L$1-360) -> 138.75651 | M5: =J5*COS(RADIANS(L5)) -> -723.11467 | N5: =J5*SIN(RADIANS(L5)) -> 634.00911 | O5: =SQRT(N5^2+M5^2) -> 961.69766 | P5: =M5-'"0" цикл 24.06'!M5 -> 0.5354791 | Q5: =N5-'"0" цикл 24.06'!N5 -> 34.322244 | R5: =SQRT(P5^2+Q5^2) -> 34.326421 | S5: =IF(R5=0,0,IF(P5>=0,DEGREES(ASIN(Q5/R5)),(180-DEGREES(ASIN(Q5/R5))))) -> 89.106171 | T5: =IF(S5<0,360+S5,S5) -> 89.106171
A6: 1.5 | B6: -4136.7 | C6: -6995.5 | D6: =(B6-C6)/2 -> 1429.4 | E6: =0.5*SIN(D6/3600*PI()/180)*1000+E7 -> -728.55878 | F6: 1763.9 | G6: 5104.4 | H6: =(F6-G6)/2 -> -1670.25 | I6: =0.5*SIN(H6/3600*PI()/180)*1000+I7 -> 640.03993 | J6: =SQRT(E6^2+I6^2) -> 969.7675 | K6: =IF(E6>=0,180-DEGREES(ASIN(-I6/J6)),IF(E6<0,DEGREES(ASIN(-I6/J6)),360-DEGREES(ASIN(I6/J6)))) -> -41.299352 | L6: =IF((K6+$L$1)<=360,K6+$L$1,K6+$L$1-360) -> 138.70065 | M6: =J6*COS(RADIANS(L6)) -> -728.55878 | N6: =J6*SIN(RADIANS(L6)) -> 640.03993 | O6: =SQRT(N6^2+M6^2) -> 969.7675 | P6: =M6-'"0" цикл 24.06'!M6 -> -0.31956789 | Q6: =N6-'"0" цикл 24.06'!N6 -> 34.549 | R6: =SQRT(P6^2+Q6^2) -> 34.550478 | S6: =IF(R6=0,0,IF(P6>=0,DEGREES(ASIN(Q6/R6)),(180-DEGREES(ASIN(Q6/R6))))) -> 90.529954 | T6: =IF(S6<0,360+S6,S6) -> 90.529954
A7: 2 | B7: -5111.1 | C7: -6225.3 | D7: =(B7-C7)/2 -> 557.1 | E7: =0.5*SIN(D7/3600*PI()/180)*1000+E8 -> -732.02372 | F7: 2687.4 | G7: 4287.7 | H7: =(F7-G7)/2 -> -800.15 | I7: =0.5*SIN(H7/3600*PI()/180)*1000+I8 -> 644.08868 | J7: =SQRT(E7^2+I7^2) -> 975.04305 | K7: =IF(E7>=0,180-DEGREES(ASIN(-I7/J7)),IF(E7<0,DEGREES(ASIN(-I7/J7)),360-DEGREES(ASIN(I7/J7)))) -> -41.34371 | L7: =IF((K7+$L$1)<=360,K7+$L$1,K7+$L$1-360) -> 138.65629 | M7: =J7*COS(RADIANS(L7)) -> -732.02372 | N7: =J7*SIN(RADIANS(L7)) -> 644.08868 | O7: =SQRT(N7^2+M7^2) -> 975.04305 | P7: =M7-'"0" цикл 24.06'!M7 -> -1.5394601 | Q7: =N7-'"0" цикл 24.06'!N7 -> 35.33462 | R7: =SQRT(P7^2+Q7^2) -> 35.368139 | S7: =IF(R7=0,0,IF(P7>=0,DEGREES(ASIN(Q7/R7)),(180-DEGREES(ASIN(Q7/R7))))) -> 92.494687 | T7: =IF(S7<0,360+S7,S7) -> 92.494687
A8: 2.5 | B8: -5815.6 | C8: -5284.1 | D8: =(B8-C8)/2 -> -265.75 | E8: =0.5*SIN(D8/3600*PI()/180)*1000+E9 -> -733.37416 | F8: 3377.6 | G8: 3299.9 | H8: =(F8-G8)/2 -> 38.85 | I8: =0.5*SIN(H8/3600*PI()/180)*1000+I9 -> 646.0283 | J8: =SQRT(E8^2+I8^2) -> 977.33834 | K8: =IF(E8>=0,180-DEGREES(ASIN(-I8/J8)),IF(E8<0,DEGREES(ASIN(-I8/J8)),360-DEGREES(ASIN(I8/J8)))) -> -41.376781 | L8: =IF((K8+$L$1)<=360,K8+$L$1,K8+$L$1-360) -> 138.62322 | M8: =J8*COS(RADIANS(L8)) -> -733.37416 | N8: =J8*SIN(RADIANS(L8)) -> 646.0283 | O8: =SQRT(N8^2+M8^2) -> 977.33834 | P8: =M8-'"0" цикл 24.06'!M8 -> -2.1407489 | Q8: =N8-'"0" цикл 24.06'!N8 -> 35.371344 | R8: =SQRT(P8^2+Q8^2) -> 35.436066 | S8: =IF(R8=0,0,IF(P8>=0,DEGREES(ASIN(Q8/R8)),(180-DEGREES(ASIN(Q8/R8))))) -> 93.463438 | T8: =IF(S8<0,360+S8,S8) -> 93.463438
A9: 3 | B9: -6633.7 | C9: -4219.2 | D9: =(B9-C9)/2 -> -1207.25 | E9: =0.5*SIN(D9/3600*PI()/180)*1000+E10 -> -732.72997 | F9: 4214.3 | G9: 2286.3 | H9: =(F9-G9)/2 -> 964 | I9: =0.5*SIN(H9/3600*PI()/180)*1000+I10 -> 645.93412 | J9: =SQRT(E9^2+I9^2) -> 976.79276 | K9: =IF(E9>=0,180-DEGREES(ASIN(-I9/J9)),IF(E9<0,DEGREES(ASIN(-I9/J9)),360-DEGREES(ASIN(I9/J9)))) -> -41.397613 | L9: =IF((K9+$L$1)<=360,K9+$L$1,K9+$L$1-360) -> 138.60239 | M9: =J9*COS(RADIANS(L9)) -> -732.72997 | N9: =J9*SIN(RADIANS(L9)) -> 645.93412 | O9: =SQRT(N9^2+M9^2) -> 976.79276 | P9: =M9-'"0" цикл 24.06'!M9 -> -2.4446055 | Q9: =N9-'"0" цикл 24.06'!N9 -> 35.082395 | R9: =SQRT(P9^2+Q9^2) -> 35.167464 | S9: =IF(R9=0,0,IF(P9>=0,DEGREES(ASIN(Q9/R9)),(180-DEGREES(ASIN(Q9/R9))))) -> 93.986032 | T9: =IF(S9<0,360+S9,S9) -> 93.986032
A10: 3.5 | B10: -7190.8 | C10: -3535.7 | D10: =(B10-C10)/2 -> -1827.55 | E10: =0.5*SIN(D10/3600*PI()/180)*1000+E11 -> -729.80353 | F10: 4910.3 | G10: 1513.2 | H10: =(F10-G10)/2 -> 1698.55 | I10: =0.5*SIN(H10/3600*PI()/180)*1000+I11 -> 643.59733 | J10: =SQRT(E10^2+I10^2) -> 973.05226 | K10: =IF(E10>=0,180-DEGREES(ASIN(-I10/J10)),IF(E10<0,DEGREES(ASIN(-I10/J10)),360-DEGREES(ASIN(I10/J10)))) -> -41.408346 | L10: =IF((K10+$L$1)<=360,K10+$L$1,K10+$L$1-360) -> 138.59165 | M10: =J10*COS(RADIANS(L10)) -> -729.80353 | N10: =J10*SIN(RADIANS(L10)) -> 643.59733 | O10: =SQRT(N10^2+M10^2) -> 973.05226 | P10: =M10-'"0" цикл 24.06'!M10 -> -2.4327278 | Q10: =N10-'"0" цикл 24.06'!N10 -> 34.617584 | R10: =SQRT(P10^2+Q10^2) -> 34.702958 | S10: =IF(R10=0,0,IF(P10>=0,DEGREES(ASIN(Q10/R10)),(180-DEGREES(ASIN(Q10/R10))))) -> 94.019814 | T10: =IF(S10<0,360+S10,S10) -> 94.019814
A11: 4 | B11: -6566.5 | C11: -3298.3 | D11: =(B11-C11)/2 -> -1634.1 | E11: =0.5*SIN(D11/3600*PI()/180)*1000+E12 -> -725.37348 | F11: 4134.3 | G11: 1485 | H11: =(F11-G11)/2 -> 1324.65 | I11: =0.5*SIN(H11/3600*PI()/180)*1000+I12 -> 639.47997 | J11: =SQRT(E11^2+I11^2) -> 967.00637 | K11: =IF(E11>=0,180-DEGREES(ASIN(-I11/J11)),IF(E11<0,DEGREES(ASIN(-I11/J11)),360-DEGREES(ASIN(I11/J11)))) -> -41.398988 | L11: =IF((K11+$L$1)<=360,K11+$L$1,K11+$L$1-360) -> 138.60101 | M11: =J11*COS(RADIANS(L11)) -> -725.37348 | N11: =J11*SIN(RADIANS(L11)) -> 639.47997 | O11: =SQRT(N11^2+M11^2) -> 967.00637 | P11: =M11-'"0" цикл 24.06'!M11 -> -2.6590052 | Q11: =N11-'"0" цикл 24.06'!N11 -> 34.402455 | R11: =SQRT(P11^2+Q11^2) -> 34.505061 | S11: =IF(R11=0,0,IF(P11>=0,DEGREES(ASIN(Q11/R11)),(180-DEGREES(ASIN(Q11/R11))))) -> 94.41967 | T11: =IF(S11<0,360+S11,S11) -> 94.41967
A12: 4.5 | B12: -5502.4 | C12: -3196 | D12: =(B12-C12)/2 -> -1153.2 | E12: =0.5*SIN(D12/3600*PI()/180)*1000+E13 -> -721.41235 | F12: 3082.6 | G12: 1439.1 | H12: =(F12-G12)/2 -> 821.75 | I12: =0.5*SIN(H12/3600*PI()/180)*1000+I13 -> 636.26895 | J12: =SQRT(E12^2+I12^2) -> 961.91162 | K12: =IF(E12>=0,180-DEGREES(ASIN(-I12/J12)),IF(E12<0,DEGREES(ASIN(-I12/J12)),360-DEGREES(ASIN(I12/J12)))) -> -41.411546 | L12: =IF((K12+$L$1)<=360,K12+$L$1,K12+$L$1-360) -> 138.58845 | M12: =J12*COS(RADIANS(L12)) -> -721.41235 | N12: =J12*SIN(RADIANS(L12)) -> 636.26895 | O12: =SQRT(N12^2+M12^2) -> 961.91162 | P12: =M12-'"0" цикл 24.06'!M12 -> -2.9073427 | Q12: =N12-'"0" цикл 24.06'!N12 -> 34.173627 | R12: =SQRT(P12^2+Q12^2) -> 34.297076 | S12: =IF(R12=0,0,IF(P12>=0,DEGREES(ASIN(Q12/R12)),(180-DEGREES(ASIN(Q12/R12))))) -> 94.862765 | T12: =IF(S12<0,360+S12,S12) -> 94.862765
A13: 5 | B13: -3904.2 | C13: -3479.1 | D13: =(B13-C13)/2 -> -212.55 | E13: =0.5*SIN(D13/3600*PI()/180)*1000+E14 -> -718.61693 | F13: 1543 | G13: 1729.4 | H13: =(F13-G13)/2 -> -93.2 | I13: =0.5*SIN(H13/3600*PI()/180)*1000+I14 -> 634.27698 | J13: =SQRT(E13^2+I13^2) -> 958.49756 | K13: =IF(E13>=0,180-DEGREES(ASIN(-I13/J13)),IF(E13<0,DEGREES(ASIN(-I13/J13)),360-DEGREES(ASIN(I13/J13)))) -> -41.432774 | L13: =IF((K13+$L$1)<=360,K13+$L$1,K13+$L$1-360) -> 138.56723 | M13: =J13*COS(RADIANS(L13)) -> -718.61693 | N13: =J13*SIN(RADIANS(L13)) -> 634.27698 | O13: =SQRT(N13^2+M13^2) -> 958.49756 | P13: =M13-'"0" цикл 24.06'!M13 -> -2.6828772 | Q13: =N13-'"0" цикл 24.06'!N13 -> 33.736328 | R13: =SQRT(P13^2+Q13^2) -> 33.842838 | S13: =IF(R13=0,0,IF(P13>=0,DEGREES(ASIN(Q13/R13)),(180-DEGREES(ASIN(Q13/R13))))) -> 94.546871 | T13: =IF(S13<0,360+S13,S13) -> 94.546871
A14: 5.5 | B14: -2365.5 | C14: -3469.2 | D14: =(B14-C14)/2 -> 551.85 | E14: =0.5*SIN(D14/3600*PI()/180)*1000+E15 -> -718.10169 | F14: -27.3 | G14: 1759.1 | H14: =(F14-G14)/2 -> -893.2 | I14: =0.5*SIN(H14/3600*PI()/180)*1000+I15 -> 634.5029 | J14: =SQRT(E14^2+I14^2) -> 958.26091 | K14: =IF(E14>=0,180-DEGREES(ASIN(-I14/J14)),IF(E14<0,DEGREES(ASIN(-I14/J14)),360-DEGREES(ASIN(I14/J14)))) -> -41.463288 | L14: =IF((K14+$L$1)<=360,K14+$L$1,K14+$L$1-360) -> 138.53671 | M14: =J14*COS(RADIANS(L14)) -> -718.10169 | N14: =J14*SIN(RADIANS(L14)) -> 634.5029 | O14: =SQRT(N14^2+M14^2) -> 958.26091 | P14: =M14-'"0" цикл 24.06'!M14 -> -2.267998 | Q14: =N14-'"0" цикл 24.06'!N14 -> 33.063528 | R14: =SQRT(P14^2+Q14^2) -> 33.141224 | S14: =IF(R14=0,0,IF(P14>=0,DEGREES(ASIN(Q14/R14)),(180-DEGREES(ASIN(Q14/R14))))) -> 93.924066 | T14: =IF(S14<0,360+S14,S14) -> 93.924066
... A124: 60.5 | B124: -407.5 | C124: 11666.5 | D124: =(B124-C124)/2 -> -6037 | E124: =0.5*SIN(D124/3600*PI()/180)*1000+E125 -> -14.632012 | F124: -4020.9 | G124: -13408.3 | H124: =(F124-G124)/2 -> 4693.7 | I124: =0.5*SIN(H124/3600*PI()/180)*1000+I125 -> 11.376868 | J124: =SQRT(E124^2+I124^2) -> 18.534532 | K124: =IF(E124>=0,180-DEGREES(ASIN(-I124/J124)),IF(E124<0,DEGREES(ASIN(-I124/J124)),360-DEGREES(ASIN(I124/J124)))) -> -37.866234 | L124: =IF((K124+$L$1)<=360,K124+$L$1,K124+$L$1-360) -> 142.13377 | M124: =J124*COS(RADIANS(L124)) -> -14.632012 | N124: =J124*SIN(RADIANS(L124)) -> 11.376868 | O124: =SQRT(N124^2+M124^2) -> 18.534532 | P124: =M124-'"0" цикл 24.06'!M124 -> -14.632012 | Q124: =N124-'"0" цикл 24.06'!N124 -> 11.376868 | R124: =SQRT(P124^2+Q124^2) -> 18.534532 | S124: =IF(R124=0,0,IF(P124>=0,DEGREES(ASIN(Q124/R124)),(180-DEGREES(ASIN(Q124/R124))))) -> 142.13377 | T124: =IF(S124<0,360+S124,S124) -> 142.13377
A125: 61 | D125: =(B125-C125)/2 -> 0 | E125: 0 | H125: =(F125-G125)/2 -> 0 | I125: 0 | J125: =SQRT(E125^2+I125^2) -> 0 | K125: 0 | L125: 0 | M125: =J125*COS(RADIANS(L125)) -> 0 | N125: =J125*SIN(RADIANS(L125)) -> 0 | O125: =SQRT(N125^2+M125^2) -> 0 | P125: =N125 -> 0 | Q125: =SQRT(O125^2+P125^2) -> 0 | R125: =IF(Q125=0,0,IF(O125>=0,DEGREES(ASIN(P125/Q125)),(180-DEGREES(ASIN(P125/Q125))))) -> 0 | S125: =IF(R125<0,360+R125,R125) -> 0 | T125: =IF(S125<0,360+S125,S125) -> 0

Sheet 2
B1: Цикл 2 (01.03.24) | K1: Аз скв | L1: 180
A2: Глубина | B2: X1 | C2: X2 | D2: X абсолютное (угл. Сек) | E2: Перемещение по X, (мм), 01.03.24 | F2: Y1 | G2: Y2 | H2: Y абсолютное (угл. Сек) | I2: Перемещение по Y, (мм), 15.03.24 | J2: Суммарное перемещение, мм | K2: Азимут (в системе координат скважины) | L2: Азимут, абсолютный | M2: D сев | N2: D восток | O2: ΔD сев | P2: ΔD восток | Q2: ΔD | S2: Аз откл
A3: -0.5 | B3: -3764 | C3: 163 | D3: =(B3-C3)/2 -> -1963.5 | E3: =0.5*SIN(D3/3600*PI()/180)*1000+E4 -> -200.38156 | F3: -3702 | G3: 228 | H3: =(F3-G3)/2 -> -1965 | I3: =0.5*SIN(H3/3600*PI()/180)*1000+I4 -> -202.1838 | J3: =SQRT(E3^2+I3^2) -> 284.65954 | K3: =IF(E3>=0,180-DEGREES(ASIN(-I3/J3)),IF(E3<0,DEGREES(ASIN(-I3/J3)),360-DEGREES(ASIN(I3/J3)))) -> 45.256505 | L3: =IF((K3+$L$1)<=360,K3+$L$1,K3+$L$1-360) -> 225.25651 | M3: =J3*COS(RADIANS(L3)) -> -200.38156 | N3: =J3*SIN(RADIANS(L3)) -> -202.1838 | O3: =M3-'"0" цикл 24.06'!#REF! -> #REF! | P3: =N3-'"0" цикл 24.06'!#REF! -> #REF! | Q3: =SQRT(O3^2+P3^2) -> #REF! | R3: =IF(Q3=0,0,IF(O3>=0,DEGREES(ASIN(P3/Q3)),(180-DEGREES(ASIN(P3/Q3))))) -> #REF! | S3: =IF(R3<0,360+R3,R3) -> #REF!
A4: 0 | B4: -3132 | C4: -482 | D4: =(B4-C4)/2 -> -1325 | E4: =0.5*SIN(D4/3600*PI()/180)*1000+E5 -> -195.62197 | F4: -3010 | G4: -428 | H4: =(F4-G4)/2 -> -1291 | I4: =0.5*SIN(H4/3600*PI()/180)*1000+I5 -> -197.42057 | J4: =SQRT(E4^2+I4^2) -> 277.92596 | K4: =IF(E4>=0,180-DEGREES(ASIN(-I4/J4)),IF(E4<0,DEGREES(ASIN(-I4/J4)),360-DEGREES(ASIN(I4/J4)))) -> 45.26219 | L4: =IF((K4+$L$1)<=360,K4+$L$1,K4+$L$1-360) -> 225.26219 | M4: =J4*COS(RADIANS(L4)) -> -195.62197 | N4: =J4*SIN(RADIANS(L4)) -> -197.42057 | O4: =M4-'"0" цикл 24.06'!M3 -> 516.92184 | P4: =N4-'"0" цикл 24.06'!N3 -> -784.12197 | Q4: =SQRT(O4^2+P4^2) -> 939.17808 | R4: =IF(Q4=0,0,IF(O4>=0,DEGREES(ASIN(P4/Q4)),(180-DEGREES(ASIN(P4/Q4))))) -> -56.605671 | S4: =IF(R4<0,360+R4,R4) -> 303.39433
A5: 0.5 | B5: -2392 | C5: -1218 | D5: =(B5-C5)/2 -> -587 | E5: =0.5*SIN(D5/3600*PI()/180)*1000+E6 -> -192.4101 | F5: -2302 | G5: -1171 | H5: =(F5-G5)/2 -> -565.5 | I5: =0.5*SIN(H5/3600*PI()/180)*1000+I6 -> -194.29112 | J5: =SQRT(E5^2+I5^2) -> 273.44229 | K5: =IF(E5>=0,180-DEGREES(ASIN(-I5/J5)),IF(E5<0,DEGREES(ASIN(-I5/J5)),360-DEGREES(ASIN(I5/J5)))) -> 45.2787 | L5: =IF((K5+$L$1)<=360,K5+$L$1,K5+$L$1-360) -> 225.2787 | M5: =J5*COS(RADIANS(L5)) -> -192.4101 | N5: =J5*SIN(RADIANS(L5)) -> -194.29112 | O5: =M5-'"0" цикл 24.06'!M4 -> 524.61381 | P5: =N5-'"0" цикл 24.06'!N4 -> -786.51214 | Q5: =SQRT(O5^2+P5^2) -> 945.42107 | R5: =IF(Q5=0,0,IF(O5>=0,DEGREES(ASIN(P5/Q5)),(180-DEGREES(ASIN(P5/Q5))))) -> -56.296197 | S5: =IF(R5<0,360+R5,R5) -> 303.7038
A6: 1 | B6: -2936 | C6: -637 | D6: =(B6-C6)/2 -> -1149.5 | E6: =0.5*SIN(D6/3600*PI()/180)*1000+E7 -> -190.98717 | F6: -2912 | G6: -547 | H6: =(F6-G6)/2 -> -1182.5 | I6: =0.5*SIN(H6/3600*PI()/180)*1000+I7 -> -192.92031 | J6: =SQRT(E6^2+I6^2) -> 271.46703 | K6: =IF(E6>=0,180-DEGREES(ASIN(-I6/J6)),IF(E6<0,DEGREES(ASIN(-I6/J6)),360-DEGREES(ASIN(I6/J6)))) -> 45.288506 | L6: =IF((K6+$L$1)<=360,K6+$L$1,K6+$L$1-360) -> 225.28851 | M6: =J6*COS(RADIANS(L6)) -> -190.98717 | N6: =J6*SIN(RADIANS(L6)) -> -192.92031 | O6: =M6-'"0" цикл 24.06'!M5 -> 532.66298 | P6: =N6-'"0" цикл 24.06'!N5 -> -792.60718 | Q6: =SQRT(O6^2+P6^2) -> 954.96387 | R6: =IF(Q6=0,0,IF(O6>=0,DEGREES(ASIN(P6/Q6)),(180-DEGREES(ASIN(P6/Q6))))) -> -56.097358 | S6: =IF(R6<0,360+R6,R6) -> 303.90264
A7: 1.5 | B7: -3302 | C7: -308 | D7: =(B7-C7)/2 -> -1497 | E7: =0.5*SIN(D7/3600*PI()/180)*1000+E8 -> -188.20072 | F7: -3200 | G7: -222 | H7: =(F7-G7)/2 -> -1489 | I7: =0.5*SIN(H7/3600*PI()/180)*1000+I8 -> -190.05387 | J7: =SQRT(E7^2+I7^2) -> 267.4696 | K7: =IF(E7>=0,180-DEGREES(ASIN(-I7/J7)),IF(E7<0,DEGREES(ASIN(-I7/J7)),360-DEGREES(ASIN(I7/J7)))) -> 45.280701 | L7: =IF((K7+$L$1)<=360,K7+$L$1,K7+$L$1-360) -> 225.2807 | M7: =J7*COS(RADIANS(L7)) -> -188.20072 | N7: =J7*SIN(RADIANS(L7)) -> -190.05387 | O7: =M7-'"0" цикл 24.06'!M6 -> 540.03849 | P7: =N7-'"0" цикл 24.06'!N6 -> -795.54479 | Q7: =SQRT(O7^2+P7^2) -> 961.52644 | R7: =IF(Q7=0,0,IF(O7>=0,DEGREES(ASIN(P7/Q7)),(180-DEGREES(ASIN(P7/Q7))))) -> -55.830221 | S7: =IF(R7<0,360+R7,R7) -> 304.16978
A8: 2 | B8: -3018 | C8: -669 | D8: =(B8-C8)/2 -> -1174.5 | E8: =0.5*SIN(D8/3600*PI()/180)*1000+E9 -> -184.57192 | F8: -2928 | G8: -615 | H8: =(F8-G8)/2 -> -1156.5 | I8: =0.5*SIN(H8/3600*PI()/180)*1000+I9 -> -186.44446 | J8: =SQRT(E8^2+I8^2) -> 262.35154 | K8: =IF(E8>=0,180-DEGREES(ASIN(-I8/J8)),IF(E8<0,DEGREES(ASIN(-I8/J8)),360-DEGREES(ASIN(I8/J8)))) -> 45.289172 | L8: =IF((K8+$L$1)<=360,K8+$L$1,K8+$L$1-360) -> 225.28917 | M8: =J8*COS(RADIANS(L8)) -> -184.57192 | N8: =J8*SIN(RADIANS(L8)) -> -186.44446 | O8: =M8-'"0" цикл 24.06'!M7 -> 545.91233 | P8: =N8-'"0" цикл 24.06'!N7 -> -795.19852 | Q8: =SQRT(O8^2+P8^2) -> 964.55221 | R8: =IF(Q8=0,0,IF(O8>=0,DEGREES(ASIN(P8/Q8)),(180-DEGREES(ASIN(P8/Q8))))) -> -55.529983 | S8: =IF(R8<0,360+R8,R8) -> 304.47002
A9: 2.5 | B9: -3583 | C9: 91 | D9: =(B9-C9)/2 -> -1837 | E9: =0.5*SIN(D9/3600*PI()/180)*1000+E10 -> -181.72487 | F9: -3558 | G9: 171 | H9: =(F9-G9)/2 -> -1864.5 | I9: =0.5*SIN(H9/3600*PI()/180)*1000+I10 -> -183.64104 | J9: =SQRT(E9^2+I9^2) -> 258.35627 | K9: =IF(E9>=0,180-DEGREES(ASIN(-I9/J9)),IF(E9<0,DEGREES(ASIN(-I9/J9)),360-DEGREES(ASIN(I9/J9)))) -> 45.300486 | L9: =IF((K9+$L$1)<=360,K9+$L$1,K9+$L$1-360) -> 225.30049 | M9: =J9*COS(RADIANS(L9)) -> -181.72487 | N9: =J9*SIN(RADIANS(L9)) -> -183.64104 | O9: =M9-'"0" цикл 24.06'!M8 -> 549.50854 | P9: =N9-'"0" цикл 24.06'!N8 -> -794.29799 | Q9: =SQRT(O9^2+P9^2) -> 965.85141 | R9: =IF(Q9=0,0,IF(O9>=0,DEGREES(ASIN(P9/Q9)),(180-DEGREES(ASIN(P9/Q9))))) -> -55.323871 | S9: =IF(R9<0,360+R9,R9) -> 304.67613
A10: 3 | B10: -3849 | C10: 267 | D10: =(B10-C10)/2 -> -2058 | E10: =0.5*SIN(D10/3600*PI()/180)*1000+E11 -> -177.27192 | F10: -3765 | G10: 350 | H10: =(F10-G10)/2 -> -2057.5 | I10: =0.5*SIN(H10/3600*PI()/180)*1000+I11 -> -179.12143 | J10: =SQRT(E10^2+I10^2) -> 252.01154 | K10: =IF(E10>=0,180-DEGREES(ASIN(-I10/J10)),IF(E10<0,DEGREES(ASIN(-I10/J10)),360-DEGREES(ASIN(I10/J10)))) -> 45.297335 | L10: =IF((K10+$L$1)<=360,K10+$L$1,K10+$L$1-360) -> 225.29733 | M10: =J10*COS(RADIANS(L10)) -> -177.27192 | N10: =J10*SIN(RADIANS(L10)) -> -179.12143 | O10: =M10-'"0" цикл 24.06'!M9 -> 553.01345 | P10: =N10-'"0" цикл 24.06'!N9 -> -789.97315 | Q10: =SQRT(O10^2+P10^2) -> 964.30361 | R10: =IF(Q10=0,0,IF(O10>=0,DEGREES(ASIN(P10/Q10)),(180-DEGREES(ASIN(P10/Q10))))) -> -55.00641 | S10: =IF(R10<0,360+R10,R10) -> 304.99359
A11: 3.5 | B11: -3933 | C11: 340 | D11: =(B11-C11)/2 -> -2136.5 | E11: =0.5*SIN(D11/3600*PI()/180)*1000+E12 -> -172.28327 | F11: -4262 | G11: 374 | H11: =(F11-G11)/2 -> -2318 | I11: =0.5*SIN(H11/3600*PI()/180)*1000+I12 -> -174.13399 | J11: =SQRT(E11^2+I11^2) -> 244.95749 | K11: =IF(E11>=0,180-DEGREES(ASIN(-I11/J11)),IF(E11<0,DEGREES(ASIN(-I11/J11)),360-DEGREES(ASIN(I11/J11)))) -> 45.306098 | L11: =IF((K11+$L$1)<=360,K11+$L$1,K11+$L$1-360) -> 225.3061 | M11: =J11*COS(RADIANS(L11)) -> -172.28327 | N11: =J11*SIN(RADIANS(L11)) -> -174.13399 | O11: =M11-'"0" цикл 24.06'!M10 -> 555.08753 | P11: =N11-'"0" цикл 24.06'!N10 -> -783.11373 | Q11: =SQRT(O11^2+P11^2) -> 959.89025 | R11: =IF(Q11=0,0,IF(O11>=0,DEGREES(ASIN(P11/Q11)),(180-DEGREES(ASIN(P11/Q11))))) -> -54.670181 | S11: =IF(R11<0,360+R11,R11) -> 305.32982
A12: 4 | B12: -4528 | C12: 935 | D12: =(B12-C12)/2 -> -2731.5 | E12: =0.5*SIN(D12/3600*PI()/180)*1000+E13 -> -167.10434 | F12: -4510 | G12: 1097 | H12: =(F12-G12)/2 -> -2803.5 | I12: =0.5*SIN(H12/3600*PI()/180)*1000+I13 -> -168.51512 | J12: =SQRT(E12^2+I12^2) -> 237.32089 | K12: =IF(E12>=0,180-DEGREES(ASIN(-I12/J12)),IF(E12<0,DEGREES(ASIN(-I12/J12)),360-DEGREES(ASIN(I12/J12)))) -> 45.240842 | L12: =IF((K12+$L$1)<=360,K12+$L$1,K12+$L$1-360) -> 225.24084 | M12: =J12*COS(RADIANS(L12)) -> -167.10434 | N12: =J12*SIN(RADIANS(L12)) -> -168.51512 | O12: =M12-'"0" цикл 24.06'!M11 -> 555.61014 | P12: =N12-'"0" цикл 24.06'!N11 -> -773.59263 | Q12: =SQRT(O12^2+P12^2) -> 952.44327 | R12: =IF(Q12=0,0,IF(O12>=0,DEGREES(ASIN(P12/Q12)),(180-DEGREES(ASIN(P12/Q12))))) -> -54.313315 | S12: =IF(R12<0,360+R12,R12) -> 305.68668
A13: 4.5 | B13: -5716 | C13: 2116 | D13: =(B13-C13)/2 -> -3916 | E13: =0.5*SIN(D13/3600*PI()/180)*1000+E14 -> -160.48319 | F13: -5668 | G13: 2227 | H13: =(F13-G13)/2 -> -3947.5 | I13: =0.5*SIN(H13/3600*PI()/180)*1000+I14 -> -161.71945 | J13: =SQRT(E13^2+I13^2) -> 227.83335 | K13: =IF(E13>=0,180-DEGREES(ASIN(-I13/J13)),IF(E13<0,DEGREES(ASIN(-I13/J13)),360-DEGREES(ASIN(I13/J13)))) -> 45.219838 | L13: =IF((K13+$L$1)<=360,K13+$L$1,K13+$L$1-360) -> 225.21984 | M13: =J13*COS(RADIANS(L13)) -> -160.48319 | N13: =J13*SIN(RADIANS(L13)) -> -161.71945 | O13: =M13-'"0" цикл 24.06'!M12 -> 558.02182 | P13: =N13-'"0" цикл 24.06'!N12 -> -763.81477 | Q13: =SQRT(O13^2+P13^2) -> 945.93941 | R13: =IF(Q13=0,0,IF(O13>=0,DEGREES(ASIN(P13/Q13)),(180-DEGREES(ASIN(P13/Q13))))) -> -53.849175 | S13: =IF(R13<0,360+R13,R13) -> 306.15082
A14: 5 | B14: -7080 | C14: 3467 | D14: =(B14-C14)/2 -> -5273.5 | E14: =0.5*SIN(D14/3600*PI()/180)*1000+E15 -> -150.99111 | F14: -7005 | G14: 3515 | H14: =(F14-G14)/2 -> -5260 | I14: =0.5*SIN(H14/3600*PI()/180)*1000+I15 -> -152.15102 | J14: =SQRT(E14^2+I14^2) -> 214.35542 | K14: =IF(E14>=0,180-DEGREES(ASIN(-I14/J14)),IF(E14<0,DEGREES(ASIN(-I14/J14)),360-DEGREES(ASIN(I14/J14)))) -> 45.219231 | L14: =IF((K14+$L$1)<=360,K14+$L$1,K14+$L$1-360) -> 225.21923 | M14: =J14*COS(RADIANS(L14)) -> -150.99111 | N14: =J14*SIN(RADIANS(L14)) -> -152.15102 | O14: =M14-'"0" цикл 24.06'!M13 -> 564.94295 | P14: =N14-'"0" цикл 24.06'!N13 -> -752.69167 | Q14: =SQRT(O14^2+P14^2) -> 941.11917 | R14: =IF(Q14=0,0,IF(O14>=0,DEGREES(ASIN(P14/Q14)),(180-DEGREES(ASIN(P14/Q14))))) -> -53.109442 | S14: =IF(R14<0,360+R14,R14) -> 306.89056
A15: 5.5 | B15: -8056 | C15: 4521 | D15: =(B15-C15)/2 -> -6288.5 | E15: =0.5*SIN(D15/3600*PI()/180)*1000+E16 -> -138.20917 | F15: -8031 | G15: 4599 | H15: =(F15-G15)/2 -> -6315 | I15: =0.5*SIN(H15/3600*PI()/180)*1000+I16 -> -139.40181 | J15: =SQRT(E15^2+I15^2) -> 196.30242 | K15: =IF(E15>=0,180-DEGREES(ASIN(-I15/J15)),IF(E15<0,DEGREES(ASIN(-I15/J15)),360-DEGREES(ASIN(I15/J15)))) -> 45.246144 | L15: =IF((K15+$L$1)<=360,K15+$L$1,K15+$L$1-360) -> 225.24614 | M15: =J15*COS(RADIANS(L15)) -> -138.20917 | N15: =J15*SIN(RADIANS(L15)) -> -139.40181 | O15: =M15-'"0" цикл 24.06'!M14 -> 577.62452 | P15: =N15-'"0" цикл 24.06'!N14 -> -740.84118 | Q15: =SQRT(O15^2+P15^2) -> 939.41245 | R15: =IF(Q15=0,0,IF(O15>=0,DEGREES(ASIN(P15/Q15)),(180-DEGREES(ASIN(P15/Q15))))) -> -52.056907 | S15: =IF(R15<0,360+R15,R15) -> 307.94309
... A53: 24.5 | B53: -632 | C53: -2847 | D53: =(B53-C53)/2 -> 1107.5 | E53: =0.5*SIN(D53/3600*PI()/180)*1000+E54 -> 5.3692857 | F53: -548 | G53: -2662 | H53: =(F53-G53)/2 -> 1057 | I53: =0.5*SIN(H53/3600*PI()/180)*1000+I54 -> 5.1244582 | J53: =SQRT(E53^2+I53^2) -> 7.4222167 | K53: =IF(E53>=0,180-DEGREES(ASIN(-I53/J53)),IF(E53<0,DEGREES(ASIN(-I53/J53)),360-DEGREES(ASIN(I53/J53)))) -> 223.66349 | L53: =IF((K53+$L$1)<=360,K53+$L$1,K53+$L$1-360) -> 43.663486 | M53: =J53*COS(RADIANS(L53)) -> 5.3692857 | N53: =J53*SIN(RADIANS(L53)) -> 5.1244582 | O53: =M53-'"0" цикл 24.06'!M52 -> 703.7103 | P53: =N53-'"0" цикл 24.06'!N52 -> -618.16731 | Q53: =SQRT(O53^2+P53^2) -> 936.66377 | R53: =IF(Q53=0,0,IF(O53>=0,DEGREES(ASIN(P53/Q53)),(180-DEGREES(ASIN(P53/Q53))))) -> -41.297367 | S53: =IF(R53<0,360+R53,R53) -> 318.70263
A54: 25 | B54: -632 | C54: -2847 | D54: =(B54-C54)/2 -> 1107.5 | E54: =0.5*SIN(D54/3600*PI()/180)*1000+E55 -> 2.6846429 | F54: -548 | G54: -2662 | H54: =(F54-G54)/2 -> 1057 | I54: =0.5*SIN(H54/3600*PI()/180)*1000+I55 -> 2.5622291 | J54: =SQRT(E54^2+I54^2) -> 3.7111084 | K54: =IF(E54>=0,180-DEGREES(ASIN(-I54/J54)),IF(E54<0,DEGREES(ASIN(-I54/J54)),360-DEGREES(ASIN(I54/J54)))) -> 223.66349 | L54: 0 | M54: =J54*COS(RADIANS(L54)) -> 3.7111084 | N54: =J54*SIN(RADIANS(L54)) -> 0 | O54: =M54-'"0" цикл 24.06'!M53 -> 687.02371 | P54: =N54-'"0" цикл 24.06'!N53 -> -609.23572 | Q54: =SQRT(O54^2+P54^2) -> 918.24275 | R54: =IF(Q54=0,0,IF(O54>=0,DEGREES(ASIN(P54/Q54)),(180-DEGREES(ASIN(P54/Q54))))) -> -41.565822 | S54: =IF(R54<0,360+R54,R54) -> 318.43418

Sheet 3
B1: Цикл 3 (01.03.24) | K1: Аз скв | L1: 180
A2: Глубина | B2: X1 | C2: X2 | D2: X абсолютное (угл. Сек) | E2: Перемещение по X, (мм), 01.03.24 | F2: Y1 | G2: Y2 | H2: Y абсолютное (угл. Сек) | I2: Перемещение по Y, (мм), 15.03.24 | J2: Суммарное перемещение, мм | K2: Азимут (в системе координат скважины) | L2: Азимут, абсолютный | M2: D сев | N2: D восток | O2: ΔD сев | P2: ΔD восток | Q2: ΔD | S2: Аз откл
A3: -0.5 | B3: -3764 | C3: 163 | D3: =(B3-C3)/2 -> -1963.5 | E3: =0.5*SIN(D3/3600*PI()/180)*1000+E4 -> -200.38156 | F3: -3702 | G3: 228 | H3: =(F3-G3)/2 -> -1965 | I3: =0.5*SIN(H3/3600*PI()/180)*1000+I4 -> -202.1838 | J3: =SQRT(E3^2+I3^2) -> 284.65954 | K3: =IF(E3>=0,180-DEGREES(ASIN(-I3/J3)),IF(E3<0,DEGREES(ASIN(-I3/J3)),360-DEGREES(ASIN(I3/J3)))) -> 45.256505 | L3: =IF((K3+$L$1)<=360,K3+$L$1,K3+$L$1-360) -> 225.25651 | M3: =J3*COS(RADIANS(L3)) -> -200.38156 | N3: =J3*SIN(RADIANS(L3)) -> -202.1838 | O3: =M3-'"0" цикл 24.06'!#REF! -> #REF! | P3: =N3-'"0" цикл 24.06'!#REF! -> #REF! | Q3: =SQRT(O3^2+P3^2) -> #REF! | R3: =IF(Q3=0,0,IF(O3>=0,DEGREES(ASIN(P3/Q3)),(180-DEGREES(ASIN(P3/Q3))))) -> #REF! | S3: =IF(R3<0,360+R3,R3) -> #REF!
A4: 0 | B4: -3132 | C4: -482 | D4: =(B4-C4)/2 -> -1325 | E4: =0.5*SIN(D4/3600*PI()/180)*1000+E5 -> -195.62197 | F4: -3010 | G4: -428 | H4: =(F4-G4)/2 -> -1291 | I4: =0.5*SIN(H4/3600*PI()/180)*1000+I5 -> -197.42057 | J4: =SQRT(E4^2+I4^2) -> 277.92596 | K4: =IF(E4>=0,180-DEGREES(ASIN(-I4/J4)),IF(E4<0,DEGREES(ASIN(-I4/J4)),360-DEGREES(ASIN(I4/J4)))) -> 45.26219 | L4: =IF((K4+$L$1)<=360,K4+$L$1,K4+$L$1-360) -> 225.26219 | M4: =J4*COS(RADIANS(L4)) -> -195.62197 | N4: =J4*SIN(RADIANS(L4)) -> -197.42057 | O4: =M4-'"0" цикл 24.06'!M3 -> 516.92184 | P4: =N4-'"0" цикл 24.06'!N3 -> -784.12197 | Q4: =SQRT(O4^2+P4^2) -> 939.17808 | R4: =IF(Q4=0,0,IF(O4>=0,DEGREES(ASIN(P4/Q4)),(180-DEGREES(ASIN(P4/Q4))))) -> -56.605671 | S4: =IF(R4<0,360+R4,R4) -> 303.39433
A5: 0.5 | B5: -2392 | C5: -1218 | D5: =(B5-C5)/2 -> -587 | E5: =0.5*SIN(D5/3600*PI()/180)*1000+E6 -> -192.4101 | F5: -2302 | G5: -1171 | H5: =(F5-G5)/2 -> -565.5 | I5: =0.5*SIN(H5/3600*PI()/180)*1000+I6 -> -194.29112 | J5: =SQRT(E5^2+I5^2) -> 273.44229 | K5: =IF(E5>=0,180-DEGREES(ASIN(-I5/J5)),IF(E5<0,DEGREES(ASIN(-I5/J5)),360-DEGREES(ASIN(I5/J5)))) -> 45.2787 | L5: =IF((K5+$L$1)<=360,K5+$L$1,K5+$L$1-360) -> 225.2787 | M5: =J5*COS(RADIANS(L5)) -> -192.4101 | N5: =J5*SIN(RADIANS(L5)) -> -194.29112 | O5: =M5-'"0" цикл 24.06'!M4 -> 524.61381 | P5: =N5-'"0" цикл 24.06'!N4 -> -786.51214 | Q5: =SQRT(O5^2+P5^2) -> 945.42107 | R5: =IF(Q5=0,0,IF(O5>=0,DEGREES(ASIN(P5/Q5)),(180-DEGREES(ASIN(P5/Q5))))) -> -56.296197 | S5: =IF(R5<0,360+R5,R5) -> 303.7038
A6: 1 | B6: -2936 | C6: -637 | D6: =(B6-C6)/2 -> -1149.5 | E6: =0.5*SIN(D6/3600*PI()/180)*1000+E7 -> -190.98717 | F6: -2912 | G6: -547 | H6: =(F6-G6)/2 -> -1182.5 | I6: =0.5*SIN(H6/3600*PI()/180)*1000+I7 -> -192.92031 | J6: =SQRT(E6^2+I6^2) -> 271.46703 | K6: =IF(E6>=0,180-DEGREES(ASIN(-I6/J6)),IF(E6<0,DEGREES(ASIN(-I6/J6)),360-DEGREES(ASIN(I6/J6)))) -> 45.288506 | L6: =IF((K6+$L$1)<=360,K6+$L$1,K6+$L$1-360) -> 225.28851 | M6: =J6*COS(RADIANS(L6)) -> -190.98717 | N6: =J6*SIN(RADIANS(L6)) -> -192.92031 | O6: =M6-'"0" цикл 24.06'!M5 -> 532.66298 | P6: =N6-'"0" цикл 24.06'!N5 -> -792.60718 | Q6: =SQRT(O6^2+P6^2) -> 954.96387 | R6: =IF(Q6=0,0,IF(O6>=0,DEGREES(ASIN(P6/Q6)),(180-DEGREES(ASIN(P6/Q6))))) -> -56.097358 | S6: =IF(R6<0,360+R6,R6) -> 303.90264
A7: 1.5 | B7: -3302 | C7: -308 | D7: =(B7-C7)/2 -> -1497 | E7: =0.5*SIN(D7/3600*PI()/180)*1000+E8 -> -188.20072 | F7: -3200 | G7: -222 | H7: =(F7-G7)/2 -> -1489 | I7: =0.5*SIN(H7/3600*PI()/180)*1000+I8 -> -190.05387 | J7: =SQRT(E7^2+I7^2) -> 267.4696 | K7: =IF(E7>=0,180-DEGREES(ASIN(-I7/J7)),IF(E7<0,DEGREES(ASIN(-I7/J7)),360-DEGREES(ASIN(I7/J7)))) -> 45.280701 | L7: =IF((K7+$L$1)<=360,K7+$L$1,K7+$L$1-360) -> 225.2807 | M7: =J7*COS(RADIANS(L7)) -> -188.20072 | N7: =J7*SIN(RADIANS(L7)) -> -190.05387 | O7: =M7-'"0" цикл 24.06'!M6 -> 540.03849 | P7: =N7-'"0" цикл 24.06'!N6 -> -795.54479 | Q7: =SQRT(O7^2+P7^2) -> 961.52644 | R7: =IF(Q7=0,0,IF(O7>=0,DEGREES(ASIN(P7/Q7)),(180-DEGREES(ASIN(P7/Q7))))) -> -55.830221 | S7: =IF(R7<0,360+R7,R7) -> 304.16978
A8: 2 | B8: -3018 | C8: -669 | D8: =(B8-C8)/2 -> -1174.5 | E8: =0.5*SIN(D8/3600*PI()/180)*1000+E9 -> -184.57192 | F8: -2928 | G8: -615 | H8: =(F8-G8)/2 -> -1156.5 | I8: =0.5*SIN(H8/3600*PI()/180)*1000+I9 -> -186.44446 | J8: =SQRT(E8^2+I8^2) -> 262.35154 | K8: =IF(E8>=0,180-DEGREES(ASIN(-I8/J8)),IF(E8<0,DEGREES(ASIN(-I8/J8)),360-DEGREES(ASIN(I8/J8)))) -> 45.289172 | L8: =IF((K8+$L$1)<=360,K8+$L$1,K8+$L$1-360) -> 225.28917 | M8: =J8*COS(RADIANS(L8)) -> -184.57192 | N8: =J8*SIN(RADIANS(L8)) -> -186.44446 | O8: =M8-'"0" цикл 24.06'!M7 -> 545.91233 | P8: =N8-'"0" цикл 24.06'!N7 -> -795.19852 | Q8: =SQRT(O8^2+P8^2) -> 964.55221 | R8: =IF(Q8=0,0,IF(O8>=0,DEGREES(ASIN(P8/Q8)),(180-DEGREES(ASIN(P8/Q8))))) -> -55.529983 | S8: =IF(R8<0,360+R8,R8) -> 304.47002
A9: 2.5 | B9: -3583 | C9: 91 | D9: =(B9-C9)/2 -> -1837 | E9: =0.5*SIN(D9/3600*PI()/180)*1000+E10 -> -181.72487 | F9: -3558 | G9: 171 | H9: =(F9-G9)/2 -> -1864.5 | I9: =0.5*SIN(H9/3600*PI()/180)*1000+I10 -> -183.64104 | J9: =SQRT(E9^2+I9^2) -> 258.35627 | K9: =IF(E9>=0,180-DEGREES(ASIN(-I9/J9)),IF(E9<0,DEGREES(ASIN(-I9/J9)),360-DEGREES(ASIN(I9/J9)))) -> 45.300486 | L9: =IF((K9+$L$1)<=360,K9+$L$1,K9+$L$1-360) -> 225.30049 | M9: =J9*COS(RADIANS(L9)) -> -181.72487 | N9: =J9*SIN(RADIANS(L9)) -> -183.64104 | O9: =M9-'"0" цикл 24.06'!M8 -> 549.50854 | P9: =N9-'"0" цикл 24.06'!N8 -> -794.29799 | Q9: =SQRT(O9^2+P9^2) -> 965.85141 | R9: =IF(Q9=0,0,IF(O9>=0,DEGREES(ASIN(P9/Q9)),(180-DEGREES(ASIN(P9/Q9))))) -> -55.323871 | S9: =IF(R9<0,360+R9,R9) -> 304.67613
A10: 3 | B10: -3849 | C10: 267 | D10: =(B10-C10)/2 -> -2058 | E10: =0.5*SIN(D10/3600*PI()/180)*1000+E11 -> -177.27192 | F10: -3765 | G10: 350 | H10: =(F10-G10)/2 -> -2057.5 | I10: =0.5*SIN(H10/3600*PI()/180)*1000+I11 -> -179.12143 | J10: =SQRT(E10^2+I10^2) -> 252.01154 | K10: =IF(E10>=0,180-DEGREES(ASIN(-I10/J10)),IF(E10<0,DEGREES(ASIN(-I10/J10)),360-DEGREES(ASIN(I10/J10)))) -> 45.297335 | L10: =IF((K10+$L$1)<=360,K10+$L$1,K10+$L$1-360) -> 225.29733 | M10: =J10*COS(RADIANS(L10)) -> -177.27192 | N10: =J10*SIN(RADIANS(L10)) -> -179.12143 | O10: =M10-'"0" цикл 24.06'!M9 -> 553.01345 | P10: =N10-'"0" цикл 24.06'!N9 -> -789.97315 | Q10: =SQRT(O10^2+P10^2) -> 964.30361 | R10: =IF(Q10=0,0,IF(O10>=0,DEGREES(ASIN(P10/Q10)),(180-DEGREES(ASIN(P10/Q10))))) -> -55.00641 | S10: =IF(R10<0,360+R10,R10) -> 304.99359
A11: 3.5 | B11: -3933 | C11: 340 | D11: =(B11-C11)/2 -> -2136.5 | E11: =0.5*SIN(D11/3600*PI()/180)*1000+E12 -> -172.28327 | F11: -4262 | G11: 374 | H11: =(F11-G11)/2 -> -2318 | I11: =0.5*SIN(H11/3600*PI()/180)*1000+I12 -> -174.13399 | J11: =SQRT(E11^2+I11^2) -> 244.95749 | K11: =IF(E11>=0,180-DEGREES(ASIN(-I11/J11)),IF(E11<0,DEGREES(ASIN(-I11/J11)),360-DEGREES(ASIN(I11/J11)))) -> 45.306098 | L11: =IF((K11+$L$1)<=360,K11+$L$1,K11+$L$1-360) -> 225.3061 | M11: =J11*COS(RADIANS(L11)) -> -172.28327 | N11: =J11*SIN(RADIANS(L11)) -> -174.13399 | O11: =M11-'"0" цикл 24.06'!M10 -> 555.08753 | P11: =N11-'"0" цикл 24.06'!N10 -> -783.11373 | Q11: =SQRT(O11^2+P11^2) -> 959.89025 | R11: =IF(Q11=0,0,IF(O11>=0,DEGREES(ASIN(P11/Q11)),(180-DEGREES(ASIN(P11/Q11))))) -> -54.670181 | S11: =IF(R11<0,360+R11,R11) -> 305.32982
A12: 4 | B12: -4528 | C12: 935 | D12: =(B12-C12)/2 -> -2731.5 | E12: =0.5*SIN(D12/3600*PI()/180)*1000+E13 -> -167.10434 | F12: -4510 | G12: 1097 | H12: =(F12-G12)/2 -> -2803.5 | I12: =0.5*SIN(H12/3600*PI()/180)*1000+I13 -> -168.51512 | J12: =SQRT(E12^2+I12^2) -> 237.32089 | K12: =IF(E12>=0,180-DEGREES(ASIN(-I12/J12)),IF(E12<0,DEGREES(ASIN(-I12/J12)),360-DEGREES(ASIN(I12/J12)))) -> 45.240842 | L12: =IF((K12+$L$1)<=360,K12+$L$1,K12+$L$1-360) -> 225.24084 | M12: =J12*COS(RADIANS(L12)) -> -167.10434 | N12: =J12*SIN(RADIANS(L12)) -> -168.51512 | O12: =M12-'"0" цикл 24.06'!M11 -> 555.61014 | P12: =N12-'"0" цикл 24.06'!N11 -> -773.59263 | Q12: =SQRT(O12^2+P12^2) -> 952.44327 | R12: =IF(Q12=0,0,IF(O12>=0,DEGREES(ASIN(P12/Q12)),(180-DEGREES(ASIN(P12/Q12))))) -> -54.313315 | S12: =IF(R12<0,360+R12,R12) -> 305.68668
A13: 4.5 | B13: -5716 | C13: 2116 | D13: =(B13-C13)/2 -> -3916 | E13: =0.5*SIN(D13/3600*PI()/180)*1000+E14 -> -160.48319 | F13: -5668 | G13: 2227 | H13: =(F13-G13)/2 -> -3947.5 | I13: =0.5*SIN(H13/3600*PI()/180)*1000+I14 -> -161.71945 | J13: =SQRT(E13^2+I13^2) -> 227.83335 | K13: =IF(E13>=0,180-DEGREES(ASIN(-I13/J13)),IF(E13<0,DEGREES(ASIN(-I13/J13)),360-DEGREES(ASIN(I13/J13)))) -> 45.219838 | L13: =IF((K13+$L$1)<=360,K13+$L$1,K13+$L$1-360) -> 225.21984 | M13: =J13*COS(RADIANS(L13)) -> -160.48319 | N13: =J13*SIN(RADIANS(L13)) -> -161.71945 | O13: =M13-'"0" цикл 24.06'!M12 -> 558.02182 | P13: =N13-'"0" цикл 24.06'!N12 -> -763.81477 | Q13: =SQRT(O13^2+P13^2) -> 945.93941 | R13: =IF(Q13=0,0,IF(O13>=0,DEGREES(ASIN(P13/Q13)),(180-DEGREES(ASIN(P13/Q13))))) -> -53.849175 | S13: =IF(R13<0,360+R13,R13) -> 306.15082
A14: 5 | B14: -7080 | C14: 3467 | D14: =(B14-C14)/2 -> -5273.5 | E14: =0.5*SIN(D14/3600*PI()/180)*1000+E15 -> -150.99111 | F14: -7005 | G14: 3515 | H14: =(F14-G14)/2 -> -5260 | I14: =0.5*SIN(H14/3600*PI()/180)*1000+I15 -> -152.15102 | J14: =SQRT(E14^2+I14^2) -> 214.35542 | K14: =IF(E14>=0,180-DEGREES(ASIN(-I14/J14)),IF(E14<0,DEGREES(ASIN(-I14/J14)),360-DEGREES(ASIN(I14/J14)))) -> 45.219231 | L14: =IF((K14+$L$1)<=360,K14+$L$1,K14+$L$1-360) -> 225.21923 | M14: =J14*COS(RADIANS(L14)) -> -150.99111 | N14: =J14*SIN(RADIANS(L14)) -> -152.15102 | O14: =M14-'"0" цикл 24.06'!M13 -> 564.94295 | P14: =N14-'"0" цикл 24.06'!N13 -> -752.69167 | Q14: =SQRT(O14^2+P14^2) -> 941.11917 | R14: =IF(Q14=0,0,IF(O14>=0,DEGREES(ASIN(P14/Q14)),(180-DEGREES(ASIN(P14/Q14))))) -> -53.109442 | S14: =IF(R14<0,360+R14,R14) -> 306.89056
A15: 5.5 | B15: -8056 | C15: 4521 | D15: =(B15-C15)/2 -> -6288.5 | E15: =0.5*SIN(D15/3600*PI()/180)*1000+E16 -> -138.20917 | F15: -8031 | G15: 4599 | H15: =(F15-G15)/2 -> -6315 | I15: =0.5*SIN(H15/3600*PI()/180)*1000+I16 -> -139.40181 | J15: =SQRT(E15^2+I15^2) -> 196.30242 | K15: =IF(E15>=0,180-DEGREES(ASIN(-I15/J15)),IF(E15<0,DEGREES(ASIN(-I15/J15)),360-DEGREES(ASIN(I15/J15)))) -> 45.246144 | L15: =IF((K15+$L$1)<=360,K15+$L$1,K15+$L$1-360) -> 225.24614 | M15: =J15*COS(RADIANS(L15)) -> -138.20917 | N15: =J15*SIN(RADIANS(L15)) -> -139.40181 | O15: =M15-'"0" цикл 24.06'!M14 -> 577.62452 | P15: =N15-'"0" цикл 24.06'!N14 -> -740.84118 | Q15: =SQRT(O15^2+P15^2) -> 939.41245 | R15: =IF(Q15=0,0,IF(O15>=0,DEGREES(ASIN(P15/Q15)),(180-DEGREES(ASIN(P15/Q15))))) -> -52.056907 | S15: =IF(R15<0,360+R15,R15) -> 307.94309
... A53: 24.5 | B53: -632 | C53: -2847 | D53: =(B53-C53)/2 -> 1107.5 | E53: =0.5*SIN(D53/3600*PI()/180)*1000+E54 -> 5.3692857 | F53: -548 | G53: -2662 | H53: =(F53-G53)/2 -> 1057 | I53: =0.5*SIN(H53/3600*PI()/180)*1000+I54 -> 5.1244582 | J53: =SQRT(E53^2+I53^2) -> 7.4222167 | K53: =IF(E53>=0,180-DEGREES(ASIN(-I53/J53)),IF(E53<0,DEGREES(ASIN(-I53/J53)),360-DEGREES(ASIN(I53/J53)))) -> 223.66349 | L53: =IF((K53+$L$1)<=360,K53+$L$1,K53+$L$1-360) -> 43.663486 | M53: =J53*COS(RADIANS(L53)) -> 5.3692857 | N53: =J53*SIN(RADIANS(L53)) -> 5.1244582 | O53: =M53-'"0" цикл 24.06'!M52 -> 703.7103 | P53: =N53-'"0" цикл 24.06'!N52 -> -618.16731 | Q53: =SQRT(O53^2+P53^2) -> 936.66377 | R53: =IF(Q53=0,0,IF(O53>=0,DEGREES(ASIN(P53/Q53)),(180-DEGREES(ASIN(P53/Q53))))) -> -41.297367 | S53: =IF(R53<0,360+R53,R53) -> 318.70263
A54: 25 | B54: -632 | C54: -2847 | D54: =(B54-C54)/2 -> 1107.5 | E54: =0.5*SIN(D54/3600*PI()/180)*1000+E55 -> 2.6846429 | F54: -548 | G54: -2662 | H54: =(F54-G54)/2 -> 1057 | I54: =0.5*SIN(H54/3600*PI()/180)*1000+I55 -> 2.5622291 | J54: =SQRT(E54^2+I54^2) -> 3.7111084 | K54: =IF(E54>=0,180-DEGREES(ASIN(-I54/J54)),IF(E54<0,DEGREES(ASIN(-I54/J54)),360-DEGREES(ASIN(I54/J54)))) -> 223.66349 | L54: 0 | M54: =J54*COS(RADIANS(L54)) -> 3.7111084 | N54: =J54*SIN(RADIANS(L54)) -> 0 | O54: =M54-'"0" цикл 24.06'!M53 -> 687.02371 | P54: =N54-'"0" цикл 24.06'!N53 -> -609.23572 | Q54: =SQRT(O54^2+P54^2) -> 918.24275 | R54: =IF(Q54=0,0,IF(O54>=0,DEGREES(ASIN(P54/Q54)),(180-DEGREES(ASIN(P54/Q54))))) -> -41.565822 | S54: =IF(R54<0,360+R54,R54) -> 318.43418

Sheet 4
B1: Цикл 3 (01.03.24) | K1: Аз скв | L1: 180
A2: Глубина | B2: X1 | C2: X2 | D2: X абсолютное (угл. Сек) | E2: Перемещение по X, (мм), 01.03.24 | F2: Y1 | G2: Y2 | H2: Y абсолютное (угл. Сек) | I2: Перемещение по Y, (мм), 15.03.24 | J2: Суммарное перемещение, мм | K2: Азимут (в системе координат скважины) | L2: Азимут, абсолютный | M2: D сев | N2: D восток | O2: ΔD сев | P2: ΔD восток | Q2: ΔD | S2: Аз откл
A3: -0.5 | B3: -3764 | C3: 163 | D3: =(B3-C3)/2 -> -1963.5 | E3: =0.5*SIN(D3/3600*PI()/180)*1000+E4 -> -200.38156 | F3: -3702 | G3: 228 | H3: =(F3-G3)/2 -> -1965 | I3: =0.5*SIN(H3/3600*PI()/180)*1000+I4 -> -202.1838 | J3: =SQRT(E3^2+I3^2) -> 284.65954 | K3: =IF(E3>=0,180-DEGREES(ASIN(-I3/J3)),IF(E3<0,DEGREES(ASIN(-I3/J3)),360-DEGREES(ASIN(I3/J3)))) -> 45.256505 | L3: =IF((K3+$L$1)<=360,K3+$L$1,K3+$L$1-360) -> 225.25651 | M3: =J3*COS(RADIANS(L3)) -> -200.38156 | N3: =J3*SIN(RADIANS(L3)) -> -202.1838 | O3: =M3-'"0" цикл 24.06'!#REF! -> #REF! | P3: =N3-'"0" цикл 24.06'!#REF! -> #REF! | Q3: =SQRT(O3^2+P3^2) -> #REF! | R3: =IF(Q3=0,0,IF(O3>=0,DEGREES(ASIN(P3/Q3)),(180-DEGREES(ASIN(P3/Q3))))) -> #REF! | S3: =IF(R3<0,360+R3,R3) -> #REF!
A4: 0 | B4: -3132 | C4: -482 | D4: =(B4-C4)/2 -> -1325 | E4: =0.5*SIN(D4/3600*PI()/180)*1000+E5 -> -195.62197 | F4: -3010 | G4: -428 | H4: =(F4-G4)/2 -> -1291 | I4: =0.5*SIN(H4/3600*PI()/180)*1000+I5 -> -197.42057 | J4: =SQRT(E4^2+I4^2) -> 277.92596 | K4: =IF(E4>=0,180-DEGREES(ASIN(-I4/J4)),IF(E4<0,DEGREES(ASIN(-I4/J4)),360-DEGREES(ASIN(I4/J4)))) -> 45.26219 | L4: =IF((K4+$L$1)<=360,K4+$L$1,K4+$L$1-360) -> 225.26219 | M4: =J4*COS(RADIANS(L4)) -> -195.62197 | N4: =J4*SIN(RADIANS(L4)) -> -197.42057 | O4: =M4-'"0" цикл 24.06'!M3 -> 516.92184 | P4: =N4-'"0" цикл 24.06'!N3 -> -784.12197 | Q4: =SQRT(O4^2+P4^2) -> 939.17808 | R4: =IF(Q4=0,0,IF(O4>=0,DEGREES(ASIN(P4/Q4)),(180-DEGREES(ASIN(P4/Q4))))) -> -56.605671 | S4: =IF(R4<0,360+R4,R4) -> 303.39433
A5: 0.5 | B5: -2392 | C5: -1218 | D5: =(B5-C5)/2 -> -587 | E5: =0.5*SIN(D5/3600*PI()/180)*1000+E6 -> -192.4101 | F5: -2302 | G5: -1171 | H5: =(F5-G5)/2 -> -565.5 | I5: =0.5*SIN(H5/3600*PI()/180)*1000+I6 -> -194.29112 | J5: =SQRT(E5^2+I5^2) -> 273.44229 | K5: =IF(E5>=0,180-DEGREES(ASIN(-I5/J5)),IF(E5<0,DEGREES(ASIN(-I5/J5)),360-DEGREES(ASIN(I5/J5)))) -> 45.2787 | L5: =IF((K5+$L$1)<=360,K5+$L$1,K5+$L$1-360) -> 225.2787 | M5: =J5*COS(RADIANS(L5)) -> -192.4101 | N5: =J5*SIN(RADIANS(L5)) -> -194.29112 | O5: =M5-'"0" цикл 24.06'!M4 -> 524.61381 | P5: =N5-'"0" цикл 24.06'!N4 -> -786.51214 | Q5: =SQRT(O5^2+P5^2) -> 945.42107 | R5: =IF(Q5=0,0,IF(O5>=0,DEGREES(ASIN(P5/Q5)),(180-DEGREES(ASIN(P5/Q5))))) -> -56.296197 | S5: =IF(R5<0,360+R5,R5) -> 303.7038
A6: 1 | B6: -2936 | C6: -637 | D6: =(B6-C6)/2 -> -1149.5 | E6: =0.5*SIN(D6/3600*PI()/180)*1000+E7 -> -190.98717 | F6: -2912 | G6: -547 | H6: =(F6-G6)/2 -> -1182.5 | I6: =0.5*SIN(H6/3600*PI()/180)*1000+I7 -> -192.92031 | J6: =SQRT(E6^2+I6^2) -> 271.46703 | K6: =IF(E6>=0,180-DEGREES(ASIN(-I6/J6)),IF(E6<0,DEGREES(ASIN(-I6/J6)),360-DEGREES(ASIN(I6/J6)))) -> 45.288506 | L6: =IF((K6+$L$1)<=360,K6+$L$1,K6+$L$1-360) -> 225.28851 | M6: =J6*COS(RADIANS(L6)) -> -190.98717 | N6: =J6*SIN(RADIANS(L6)) -> -192.92031 | O6: =M6-'"0" цикл 24.06'!M5 -> 532.66298 | P6: =N6-'"0" цикл 24.06'!N5 -> -792.60718 | Q6: =SQRT(O6^2+P6^2) -> 954.96387 | R6: =IF(Q6=0,0,IF(O6>=0,DEGREES(ASIN(P6/Q6)),(180-DEGREES(ASIN(P6/Q6))))) -> -56.097358 | S6: =IF(R6<0,360+R6,R6) -> 303.90264
A7: 1.5 | B7: -3302 | C7: -308 | D7: =(B7-C7)/2 -> -1497 | E7: =0.5*SIN(D7/3600*PI()/180)*1000+E8 -> -188.20072 | F7: -3200 | G7: -222 | H7: =(F7-G7)/2 -> -1489 | I7: =0.5*SIN(H7/3600*PI()/180)*1000+I8 -> -190.05387 | J7: =SQRT(E7^2+I7^2) -> 267.4696 | K7: =IF(E7>=0,180-DEGREES(ASIN(-I7/J7)),IF(E7<0,DEGREES(ASIN(-I7/J7)),360-DEGREES(ASIN(I7/J7)))) -> 45.280701 | L7: =IF((K7+$L$1)<=360,K7+$L$1,K7+$L$1-360) -> 225.2807 | M7: =J7*COS(RADIANS(L7)) -> -188.20072 | N7: =J7*SIN(RADIANS(L7)) -> -190.05387 | O7: =M7-'"0" цикл 24.06'!M6 -> 540.03849 | P7: =N7-'"0" цикл 24.06'!N6 -> -795.54479 | Q7: =SQRT(O7^2+P7^2) -> 961.52644 | R7: =IF(Q7=0,0,IF(O7>=0,DEGREES(ASIN(P7/Q7)),(180-DEGREES(ASIN(P7/Q7))))) -> -55.830221 | S7: =IF(R7<0,360+R7,R7) -> 304.16978
A8: 2 | B8: -3018 | C8: -669 | D8: =(B8-C8)/2 -> -1174.5 | E8: =0.5*SIN(D8/3600*PI()/180)*1000+E9 -> -184.57192 | F8: -2928 | G8: -615 | H8: =(F8-G8)/2 -> -1156.5 | I8: =0.5*SIN(H8/3600*PI()/180)*1000+I9 -> -186.44446 | J8: =SQRT(E8^2+I8^2) -> 262.35154 | K8: =IF(E8>=0,180-DEGREES(ASIN(-I8/J8)),IF(E8<0,DEGREES(ASIN(-I8/J8)),360-DEGREES(ASIN(I8/J8)))) -> 45.289172 | L8: =IF((K8+$L$1)<=360,K8+$L$1,K8+$L$1-360) -> 225.28917 | M8: =J8*COS(RADIANS(L8)) -> -184.57192 | N8: =J8*SIN(RADIANS(L8)) -> -186.44446 | O8: =M8-'"0" цикл 24.06'!M7 -> 545.91233 | P8: =N8-'"0" цикл 24.06'!N7 -> -795.19852 | Q8: =SQRT(O8^2+P8^2) -> 964.55221 | R8: =IF(Q8=0,0,IF(O8>=0,DEGREES(ASIN(P8/Q8)),(180-DEGREES(ASIN(P8/Q8))))) -> -55.529983 | S8: =IF(R8<0,360+R8,R8) -> 304.47002
A9: 2.5 | B9: -3583 | C9: 91 | D9: =(B9-C9)/2 -> -1837 | E9: =0.5*SIN(D9/3600*PI()/180)*1000+E10 -> -181.72487 | F9: -3558 | G9: 171 | H9: =(F9-G9)/2 -> -1864.5 | I9: =0.5*SIN(H9/3600*PI()/180)*1000+I10 -> -183.64104 | J9: =SQRT(E9^2+I9^2) -> 258.35627 | K9: =IF(E9>=0,180-DEGREES(ASIN(-I9/J9)),IF(E9<0,DEGREES(ASIN(-I9/J9)),360-DEGREES(ASIN(I9/J9)))) -> 45.300486 | L9: =IF((K9+$L$1)<=360,K9+$L$1,K9+$L$1-360) -> 225.30049 | M9: =J9*COS(RADIANS(L9)) -> -181.72487 | N9: =J9*SIN(RADIANS(L9)) -> -183.64104 | O9: =M9-'"0" цикл 24.06'!M8 -> 549.50854 | P9: =N9-'"0" цикл 24.06'!N8 -> -794.29799 | Q9: =SQRT(O9^2+P9^2) -> 965.85141 | R9: =IF(Q9=0,0,IF(O9>=0,DEGREES(ASIN(P9/Q9)),(180-DEGREES(ASIN(P9/Q9))))) -> -55.323871 | S9: =IF(R9<0,360+R9,R9) -> 304.67613
A10: 3 | B10: -3849 | C10: 267 | D10: =(B10-C10)/2 -> -2058 | E10: =0.5*SIN(D10/3600*PI()/180)*1000+E11 -> -177.27192 | F10: -3765 | G10: 350 | H10: =(F10-G10)/2 -> -2057.5 | I10: =0.5*SIN(H10/3600*PI()/180)*1000+I11 -> -179.12143 | J10: =SQRT(E10^2+I10^2) -> 252.01154 | K10: =IF(E10>=0,180-DEGREES(ASIN(-I10/J10)),IF(E10<0,DEGREES(ASIN(-I10/J10)),360-DEGREES(ASIN(I10/J10)))) -> 45.297335 | L10: =IF((K10+$L$1)<=360,K10+$L$1,K10+$L$1-360) -> 225.29733 | M10: =J10*COS(RADIANS(L10)) -> -177.27192 | N10: =J10*SIN(RADIANS(L10)) -> -179.12143 | O10: =M10-'"0" цикл 24.06'!M9 -> 553.01345 | P10: =N10-'"0" цикл 24.06'!N9 -> -789.97315 | Q10: =SQRT(O10^2+P10^2) -> 964.30361 | R10: =IF(Q10=0,0,IF(O10>=0,DEGREES(ASIN(P10/Q10)),(180-DEGREES(ASIN(P10/Q10))))) -> -55.00641 | S10: =IF(R10<0,360+R10,R10) -> 304.99359
A11: 3.5 | B11: -3933 | C11: 340 | D11: =(B11-C11)/2 -> -2136.5 | E11: =0.5*SIN(D11/3600*PI()/180)*1000+E12 -> -172.28327 | F11: -4262 | G11: 374 | H11: =(F11-G11)/2 -> -2318 | I11: =0.5*SIN(H11/3600*PI()/180)*1000+I12 -> -174.13399 | J11: =SQRT(E11^2+I11^2) -> 244.95749 | K11: =IF(E11>=0,180-DEGREES(ASIN(-I11/J11)),IF(E11<0,DEGREES(ASIN(-I11/J11)),360-DEGREES(ASIN(I11/J11)))) -> 45.306098 | L11: =IF((K11+$L$1)<=360,K11+$L$1,K11+$L$1-360) -> 225.3061 | M11: =J11*COS(RADIANS(L11)) -> -172.28327 | N11: =J11*SIN(RADIANS(L11)) -> -174.13399 | O11: =M11-'"0" цикл 24.06'!M10 -> 555.08753 | P11: =N11-'"0" цикл 24.06'!N10 -> -783.11373 | Q11: =SQRT(O11^2+P11^2) -> 959.89025 | R11: =IF(Q11=0,0,IF(O11>=0,DEGREES(ASIN(P11/Q11)),(180-DEGREES(ASIN(P11/Q11))))) -> -54.670181 | S11: =IF(R11<0,360+R11,R11) -> 305.32982
A12: 4 | B12: -4528 | C12: 935 | D12: =(B12-C12)/2 -> -2731.5 | E12: =0.5*SIN(D12/3600*PI()/180)*1000+E13 -> -167.10434 | F12: -4510 | G12: 1097 | H12: =(F12-G12)/2 -> -2803.5 | I12: =0.5*SIN(H12/3600*PI()/180)*1000+I13 -> -168.51512 | J12: =SQRT(E12^2+I12^2) -> 237.32089 | K12: =IF(E12>=0,180-DEGREES(ASIN(-I12/J12)),IF(E12<0,DEGREES(ASIN(-I12/J12)),360-DEGREES(ASIN(I12/J12)))) -> 45.240842 | L12: =IF((K12+$L$1)<=360,K12+$L$1,K12+$L$1-360) -> 225.24084 | M12: =J12*COS(RADIANS(L12)) -> -167.10434 | N12: =J12*SIN(RADIANS(L12)) -> -168.51512 | O12: =M12-'"0" цикл 24.06'!M11 -> 555.61014 | P12: =N12-'"0" цикл 24.06'!N11 -> -773.59263 | Q12: =SQRT(O12^2+P12^2) -> 952.44327 | R12: =IF(Q12=0,0,IF(O12>=0,DEGREES(ASIN(P12/Q12)),(180-DEGREES(ASIN(P12/Q12))))) -> -54.313315 | S12: =IF(R12<0,360+R12,R12) -> 305.68668
A13: 4.5 | B13: -5716 | C13: 2116 | D13: =(B13-C13)/2 -> -3916 | E13: =0.5*SIN(D13/3600*PI()/180)*1000+E14 -> -160.48319 | F13: -5668 | G13: 2227 | H13: =(F13-G13)/2 -> -3947.5 | I13: =0.5*SIN(H13/3600*PI()/180)*1000+I14 -> -161.71945 | J13: =SQRT(E13^2+I13^2) -> 227.83335 | K13: =IF(E13>=0,180-DEGREES(ASIN(-I13/J13)),IF(E13<0,DEGREES(ASIN(-I13/J13)),360-DEGREES(ASIN(I13/J13)))) -> 45.219838 | L13: =IF((K13+$L$1)<=360,K13+$L$1,K13+$L$1-360) -> 225.21984 | M13: =J13*COS(RADIANS(L13)) -> -160.48319 | N13: =J13*SIN(RADIANS(L13)) -> -161.71945 | O13: =M13-'"0" цикл 24.06'!M12 -> 558.02182 | P13: =N13-'"0" цикл 24.06'!N12 -> -763.81477 | Q13: =SQRT(O13^2+P13^2) -> 945.93941 | R13: =IF(Q13=0,0,IF(O13>=0,DEGREES(ASIN(P13/Q13)),(180-DEGREES(ASIN(P13/Q13))))) -> -53.849175 | S13: =IF(R13<0,360+R13,R13) -> 306.15082
A14: 5 | B14: -7080 | C14: 3467 | D14: =(B14-C14)/2 -> -5273.5 | E14: =0.5*SIN(D14/3600*PI()/180)*1000+E15 -> -150.99111 | F14: -7005 | G14: 3515 | H14: =(F14-G14)/2 -> -5260 | I14: =0.5*SIN(H14/3600*PI()/180)*1000+I15 -> -152.15102 | J14: =SQRT(E14^2+I14^2) -> 214.35542 | K14: =IF(E14>=0,180-DEGREES(ASIN(-I14/J14)),IF(E14<0,DEGREES(ASIN(-I14/J14)),360-DEGREES(ASIN(I14/J14)))) -> 45.219231 | L14: =IF((K14+$L$1)<=360,K14+$L$1,K14+$L$1-360) -> 225.21923 | M14: =J14*COS(RADIANS(L14)) -> -150.99111 | N14: =J14*SIN(RADIANS(L14)) -> -152.15102 | O14: =M14-'"0" цикл 24.06'!M13 -> 564.94295 | P14: =N14-'"0" цикл 24.06'!N13 -> -752.69167 | Q14: =SQRT(O14^2+P14^2) -> 941.11917 | R14: =IF(Q14=0,0,IF(O14>=0,DEGREES(ASIN(P14/Q14)),(180-DEGREES(ASIN(P14/Q14))))) -> -53.109442 | S14: =IF(R14<0,360+R14,R14) -> 306.89056
A15: 5.5 | B15: -8056 | C15: 4521 | D15: =(B15-C15)/2 -> -6288.5 | E15: =0.5*SIN(D15/3600*PI()/180)*1000+E16 -> -138.20917 | F15: -8031 | G15: 4599 | H15: =(F15-G15)/2 -> -6315 | I15: =0.5*SIN(H15/3600*PI()/180)*1000+I16 -> -139.40181 | J15: =SQRT(E15^2+I15^2) -> 196.30242 | K15: =IF(E15>=0,180-DEGREES(ASIN(-I15/J15)),IF(E15<0,DEGREES(ASIN(-I15/J15)),360-DEGREES(ASIN(I15/J15)))) -> 45.246144 | L15: =IF((K15+$L$1)<=360,K15+$L$1,K15+$L$1-360) -> 225.24614 | M15: =J15*COS(RADIANS(L15)) -> -138.20917 | N15: =J15*SIN(RADIANS(L15)) -> -139.40181 | O15: =M15-'"0" цикл 24.06'!M14 -> 577.62452 | P15: =N15-'"0" цикл 24.06'!N14 -> -740.84118 | Q15: =SQRT(O15^2+P15^2) -> 939.41245 | R15: =IF(Q15=0,0,IF(O15>=0,DEGREES(ASIN(P15/Q15)),(180-DEGREES(ASIN(P15/Q15))))) -> -52.056907 | S15: =IF(R15<0,360+R15,R15) -> 307.94309
